2019-05-24 20:57:05 WARNING (MainThread) [homeassistant.components.http] Configuring api_password via the http component has been deprecated. Use the legacy api password auth provider instead. For instructions, see https://www.home-assistant.io/docs/authentication/providers/#legacy-api-password
2019-05-24 20:57:05 WARNING (MainThread) [homeassistant.components.http.auth] legacy_api_password support has been enabled.
2019-05-24 20:57:16 WARNING (MainThread) [homeassistant.loader] You are using a custom integration for mqtt_jkw which has not been tested by Home Assistant. This component might cause stability problems, be sure to disable it if you do experience issues with Home Assistant.
2019-05-24 20:57:16 WARNING (MainThread) [homeassistant.loader] You are using a custom integration for trash which has not been tested by Home Assistant. This component might cause stability problems, be sure to disable it if you do experience issues with Home Assistant.
2019-05-24 20:57:50 ERROR (MainThread) [homeassistant.components.owntracks.device_tracker] Can't parse topic: 'owntracks/illuminum_kolja'
2019-05-24 20:57:50 ERROR (MainThread) [homeassistant.components.owntracks.device_tracker] Exception in async_handle_message when dispatching 'owntracks': (<homeassistant.core.HomeAssistant object at 0x7f00bb351400>, <homeassistant.components.owntracks.OwnTracksContext object at 0x7f0080162e10>, {'batt': 19, '_cp': True, 'topic': 'owntracks/illuminum_kolja', 'conn': 'w', 'acc': 16, 'tst': 1522262146, '_type': 'location', 'tid': 'jk', 'lat': 52.5822077, 'lon': 10.1879147})
Traceback (most recent call last):
  File "/srv/homeassistant/lib/python3.5/site-packages/homeassistant/components/owntracks/device_tracker.py", line 351, in async_handle_message
    await handler(hass, context, message)
  File "/srv/homeassistant/lib/python3.5/site-packages/homeassistant/components/owntracks/device_tracker.py", line 156, in async_handle_location_message
    dev_id, kwargs = _parse_see_args(message, context.mqtt_topic)
  File "/srv/homeassistant/lib/python3.5/site-packages/homeassistant/components/owntracks/device_tracker.py", line 67, in _parse_see_args
    user, device = _parse_topic(message['topic'], subscribe_topic)
  File "/srv/homeassistant/lib/python3.5/site-packages/homeassistant/components/owntracks/device_tracker.py", line 54, in _parse_topic
    user, device = topic_list[user_index], topic_list[user_index + 1]
IndexError: list index out of range

2019-05-24 20:58:51 ERROR (stream_worker) [libav.mp3] Header missing
2019-05-24 20:58:52 ERROR (stream_worker) [libav.h264] error while decoding MB 23 42, bytestream -54
2019-05-24 21:03:10 WARNING (MainThread) [homeassistant.helpers.entity] Update of sensor.to_hannover is taking over 10 seconds
2019-05-24 21:03:31 WARNING (MainThread) [homeassistant.components.sensor] Updating google_travel_time sensor took longer than the scheduled update interval 0:00:30
2019-05-24 21:03:34 ERROR (MainThread) [homeassistant.core] Error doing job: Future exception was never retrieved
Traceback (most recent call last):
  File "/srv/homeassistant/lib/python3.5/site-packages/googlemaps/client.py", line 253, in _request
    result = self._get_body(response)
  File "/srv/homeassistant/lib/python3.5/site-packages/googlemaps/client.py", line 276, in _get_body
    raise googlemaps.exceptions._RetriableRequest()
googlemaps.exceptions._RetriableRequest

During handling of the above exception, another exception occurred:

Traceback (most recent call last):
  File "/srv/homeassistant/lib/python3.5/site-packages/googlemaps/client.py", line 253, in _request
    result = self._get_body(response)
  File "/srv/homeassistant/lib/python3.5/site-packages/googlemaps/client.py", line 276, in _get_body
    raise googlemaps.exceptions._RetriableRequest()
googlemaps.exceptions._RetriableRequest

During handling of the above exception, another exception occurred:

Traceback (most recent call last):
  File "/srv/homeassistant/lib/python3.5/site-packages/googlemaps/client.py", line 253, in _request
    result = self._get_body(response)
  File "/srv/homeassistant/lib/python3.5/site-packages/googlemaps/client.py", line 276, in _get_body
    raise googlemaps.exceptions._RetriableRequest()
googlemaps.exceptions._RetriableRequest

During handling of the above exception, another exception occurred:

Traceback (most recent call last):
  File "/srv/homeassistant/lib/python3.5/site-packages/googlemaps/client.py", line 253, in _request
    result = self._get_body(response)
  File "/srv/homeassistant/lib/python3.5/site-packages/googlemaps/client.py", line 276, in _get_body
    raise googlemaps.exceptions._RetriableRequest()
googlemaps.exceptions._RetriableRequest

During handling of the above exception, another exception occurred:

Traceback (most recent call last):
  File "/srv/homeassistant/lib/python3.5/site-packages/googlemaps/client.py", line 253, in _request
    result = self._get_body(response)
  File "/srv/homeassistant/lib/python3.5/site-packages/googlemaps/client.py", line 276, in _get_body
    raise googlemaps.exceptions._RetriableRequest()
googlemaps.exceptions._RetriableRequest

During handling of the above exception, another exception occurred:

Traceback (most recent call last):
  File "/srv/homeassistant/lib/python3.5/site-packages/googlemaps/client.py", line 253, in _request
    result = self._get_body(response)
  File "/srv/homeassistant/lib/python3.5/site-packages/googlemaps/client.py", line 276, in _get_body
    raise googlemaps.exceptions._RetriableRequest()
googlemaps.exceptions._RetriableRequest

During handling of the above exception, another exception occurred:

Traceback (most recent call last):
  File "/srv/homeassistant/lib/python3.5/site-packages/googlemaps/client.py", line 253, in _request
    result = self._get_body(response)
  File "/srv/homeassistant/lib/python3.5/site-packages/googlemaps/client.py", line 276, in _get_body
    raise googlemaps.exceptions._RetriableRequest()
googlemaps.exceptions._RetriableRequest

During handling of the above exception, another exception occurred:

Traceback (most recent call last):
  File "/srv/homeassistant/lib/python3.5/site-packages/googlemaps/client.py", line 253, in _request
    result = self._get_body(response)
  File "/srv/homeassistant/lib/python3.5/site-packages/googlemaps/client.py", line 276, in _get_body
    raise googlemaps.exceptions._RetriableRequest()
googlemaps.exceptions._RetriableRequest

During handling of the above exception, another exception occurred:

Traceback (most recent call last):
  File "/srv/homeassistant/lib/python3.5/site-packages/googlemaps/client.py", line 253, in _request
    result = self._get_body(response)
  File "/srv/homeassistant/lib/python3.5/site-packages/googlemaps/client.py", line 276, in _get_body
    raise googlemaps.exceptions._RetriableRequest()
googlemaps.exceptions._RetriableRequest

During handling of the above exception, another exception occurred:

Traceback (most recent call last):
  File "/srv/homeassistant/lib/python3.5/site-packages/googlemaps/client.py", line 253, in _request
    result = self._get_body(response)
  File "/srv/homeassistant/lib/python3.5/site-packages/googlemaps/client.py", line 276, in _get_body
    raise googlemaps.exceptions._RetriableRequest()
googlemaps.exceptions._RetriableRequest

During handling of the above exception, another exception occurred:

Traceback (most recent call last):
  File "/srv/homeassistant/lib/python3.5/site-packages/googlemaps/client.py", line 253, in _request
    result = self._get_body(response)
  File "/srv/homeassistant/lib/python3.5/site-packages/googlemaps/client.py", line 276, in _get_body
    raise googlemaps.exceptions._RetriableRequest()
googlemaps.exceptions._RetriableRequest

During handling of the above exception, another exception occurred:

Traceback (most recent call last):
  File "/srv/homeassistant/lib/python3.5/site-packages/googlemaps/client.py", line 253, in _request
    result = self._get_body(response)
  File "/srv/homeassistant/lib/python3.5/site-packages/googlemaps/client.py", line 276, in _get_body
    raise googlemaps.exceptions._RetriableRequest()
googlemaps.exceptions._RetriableRequest

During handling of the above exception, another exception occurred:

Traceback (most recent call last):
  File "/usr/lib/python3.5/concurrent/futures/thread.py", line 55, in run
    result = self.fn(*self.args, **self.kwargs)
  File "/srv/homeassistant/lib/python3.5/site-packages/homeassistant/components/google_travel_time/sensor.py", line 108, in run_setup
    hass, name, api_key, origin, destination, options)
  File "/srv/homeassistant/lib/python3.5/site-packages/homeassistant/components/google_travel_time/sensor.py", line 144, in __init__
    self.update()
  File "/srv/homeassistant/lib/python3.5/site-packages/homeassistant/util/__init__.py", line 224, in wrapper
    result = method(*args, **kwargs)
  File "/srv/homeassistant/lib/python3.5/site-packages/homeassistant/components/google_travel_time/sensor.py", line 225, in update
    self._origin, self._destination, **options_copy)
  File "/srv/homeassistant/lib/python3.5/site-packages/googlemaps/client.py", line 356, in wrapper
    result = func(*args, **kwargs)
  File "/srv/homeassistant/lib/python3.5/site-packages/googlemaps/distance_matrix.py", line 130, in distance_matrix
    return client._request("/maps/api/distancematrix/json", params)
  File "/srv/homeassistant/lib/python3.5/site-packages/googlemaps/client.py", line 260, in _request
    extract_body, requests_kwargs, post_json)
  File "/srv/homeassistant/lib/python3.5/site-packages/googlemaps/client.py", line 260, in _request
    extract_body, requests_kwargs, post_json)
  File "/srv/homeassistant/lib/python3.5/site-packages/googlemaps/client.py", line 260, in _request
    extract_body, requests_kwargs, post_json)
  File "/srv/homeassistant/lib/python3.5/site-packages/googlemaps/client.py", line 260, in _request
    extract_body, requests_kwargs, post_json)
  File "/srv/homeassistant/lib/python3.5/site-packages/googlemaps/client.py", line 260, in _request
    extract_body, requests_kwargs, post_json)
  File "/srv/homeassistant/lib/python3.5/site-packages/googlemaps/client.py", line 260, in _request
    extract_body, requests_kwargs, post_json)
  File "/srv/homeassistant/lib/python3.5/site-packages/googlemaps/client.py", line 260, in _request
    extract_body, requests_kwargs, post_json)
  File "/srv/homeassistant/lib/python3.5/site-packages/googlemaps/client.py", line 260, in _request
    extract_body, requests_kwargs, post_json)
  File "/srv/homeassistant/lib/python3.5/site-packages/googlemaps/client.py", line 260, in _request
    extract_body, requests_kwargs, post_json)
  File "/srv/homeassistant/lib/python3.5/site-packages/googlemaps/client.py", line 260, in _request
    extract_body, requests_kwargs, post_json)
  File "/srv/homeassistant/lib/python3.5/site-packages/googlemaps/client.py", line 260, in _request
    extract_body, requests_kwargs, post_json)
  File "/srv/homeassistant/lib/python3.5/site-packages/googlemaps/client.py", line 260, in _request
    extract_body, requests_kwargs, post_json)
  File "/srv/homeassistant/lib/python3.5/site-packages/googlemaps/client.py", line 203, in _request
    raise googlemaps.exceptions.Timeout()
googlemaps.exceptions.Timeout
2019-05-24 21:04:02 WARNING (MainThread) [homeassistant.components.sensor] Updating google_travel_time sensor took longer than the scheduled update interval 0:00:30
2019-05-24 21:04:09 ERROR (MainThread) [homeassistant.helpers.entity] Update for sensor.to_hannover fails
Traceback (most recent call last):
  File "/srv/homeassistant/lib/python3.5/site-packages/googlemaps/client.py", line 253, in _request
    result = self._get_body(response)
  File "/srv/homeassistant/lib/python3.5/site-packages/googlemaps/client.py", line 276, in _get_body
    raise googlemaps.exceptions._RetriableRequest()
googlemaps.exceptions._RetriableRequest

During handling of the above exception, another exception occurred:

Traceback (most recent call last):
  File "/srv/homeassistant/lib/python3.5/site-packages/googlemaps/client.py", line 253, in _request
    result = self._get_body(response)
  File "/srv/homeassistant/lib/python3.5/site-packages/googlemaps/client.py", line 276, in _get_body
    raise googlemaps.exceptions._RetriableRequest()
googlemaps.exceptions._RetriableRequest

During handling of the above exception, another exception occurred:

Traceback (most recent call last):
  File "/srv/homeassistant/lib/python3.5/site-packages/googlemaps/client.py", line 253, in _request
    result = self._get_body(response)
  File "/srv/homeassistant/lib/python3.5/site-packages/googlemaps/client.py", line 276, in _get_body
    raise googlemaps.exceptions._RetriableRequest()
googlemaps.exceptions._RetriableRequest

During handling of the above exception, another exception occurred:

Traceback (most recent call last):
  File "/srv/homeassistant/lib/python3.5/site-packages/googlemaps/client.py", line 253, in _request
    result = self._get_body(response)
  File "/srv/homeassistant/lib/python3.5/site-packages/googlemaps/client.py", line 276, in _get_body
    raise googlemaps.exceptions._RetriableRequest()
googlemaps.exceptions._RetriableRequest

During handling of the above exception, another exception occurred:

Traceback (most recent call last):
  File "/srv/homeassistant/lib/python3.5/site-packages/googlemaps/client.py", line 253, in _request
    result = self._get_body(response)
  File "/srv/homeassistant/lib/python3.5/site-packages/googlemaps/client.py", line 276, in _get_body
    raise googlemaps.exceptions._RetriableRequest()
googlemaps.exceptions._RetriableRequest

During handling of the above exception, another exception occurred:

Traceback (most recent call last):
  File "/srv/homeassistant/lib/python3.5/site-packages/googlemaps/client.py", line 253, in _request
    result = self._get_body(response)
  File "/srv/homeassistant/lib/python3.5/site-packages/googlemaps/client.py", line 276, in _get_body
    raise googlemaps.exceptions._RetriableRequest()
googlemaps.exceptions._RetriableRequest

During handling of the above exception, another exception occurred:

Traceback (most recent call last):
  File "/srv/homeassistant/lib/python3.5/site-packages/googlemaps/client.py", line 253, in _request
    result = self._get_body(response)
  File "/srv/homeassistant/lib/python3.5/site-packages/googlemaps/client.py", line 276, in _get_body
    raise googlemaps.exceptions._RetriableRequest()
googlemaps.exceptions._RetriableRequest

During handling of the above exception, another exception occurred:

Traceback (most recent call last):
  File "/srv/homeassistant/lib/python3.5/site-packages/googlemaps/client.py", line 253, in _request
    result = self._get_body(response)
  File "/srv/homeassistant/lib/python3.5/site-packages/googlemaps/client.py", line 276, in _get_body
    raise googlemaps.exceptions._RetriableRequest()
googlemaps.exceptions._RetriableRequest

During handling of the above exception, another exception occurred:

Traceback (most recent call last):
  File "/srv/homeassistant/lib/python3.5/site-packages/googlemaps/client.py", line 253, in _request
    result = self._get_body(response)
  File "/srv/homeassistant/lib/python3.5/site-packages/googlemaps/client.py", line 276, in _get_body
    raise googlemaps.exceptions._RetriableRequest()
googlemaps.exceptions._RetriableRequest

During handling of the above exception, another exception occurred:

Traceback (most recent call last):
  File "/srv/homeassistant/lib/python3.5/site-packages/googlemaps/client.py", line 253, in _request
    result = self._get_body(response)
  File "/srv/homeassistant/lib/python3.5/site-packages/googlemaps/client.py", line 276, in _get_body
    raise googlemaps.exceptions._RetriableRequest()
googlemaps.exceptions._RetriableRequest

During handling of the above exception, another exception occurred:

Traceback (most recent call last):
  File "/srv/homeassistant/lib/python3.5/site-packages/googlemaps/client.py", line 253, in _request
    result = self._get_body(response)
  File "/srv/homeassistant/lib/python3.5/site-packages/googlemaps/client.py", line 276, in _get_body
    raise googlemaps.exceptions._RetriableRequest()
googlemaps.exceptions._RetriableRequest

During handling of the above exception, another exception occurred:

Traceback (most recent call last):
  File "/srv/homeassistant/lib/python3.5/site-packages/homeassistant/helpers/entity.py", line 220, in async_update_ha_state
    await self.async_device_update()
  File "/srv/homeassistant/lib/python3.5/site-packages/homeassistant/helpers/entity.py", line 377, in async_device_update
    await self.hass.async_add_executor_job(self.update)
  File "/usr/lib/python3.5/asyncio/futures.py", line 380, in __iter__
    yield self  # This tells Task to wait for completion.
  File "/usr/lib/python3.5/asyncio/tasks.py", line 304, in _wakeup
    future.result()
  File "/usr/lib/python3.5/asyncio/futures.py", line 293, in result
    raise self._exception
  File "/usr/lib/python3.5/concurrent/futures/thread.py", line 55, in run
    result = self.fn(*self.args, **self.kwargs)
  File "/srv/homeassistant/lib/python3.5/site-packages/homeassistant/util/__init__.py", line 224, in wrapper
    result = method(*args, **kwargs)
  File "/srv/homeassistant/lib/python3.5/site-packages/homeassistant/components/google_travel_time/sensor.py", line 225, in update
    self._origin, self._destination, **options_copy)
  File "/srv/homeassistant/lib/python3.5/site-packages/googlemaps/client.py", line 356, in wrapper
    result = func(*args, **kwargs)
  File "/srv/homeassistant/lib/python3.5/site-packages/googlemaps/distance_matrix.py", line 130, in distance_matrix
    return client._request("/maps/api/distancematrix/json", params)
  File "/srv/homeassistant/lib/python3.5/site-packages/googlemaps/client.py", line 260, in _request
    extract_body, requests_kwargs, post_json)
  File "/srv/homeassistant/lib/python3.5/site-packages/googlemaps/client.py", line 260, in _request
    extract_body, requests_kwargs, post_json)
  File "/srv/homeassistant/lib/python3.5/site-packages/googlemaps/client.py", line 260, in _request
    extract_body, requests_kwargs, post_json)
  File "/srv/homeassistant/lib/python3.5/site-packages/googlemaps/client.py", line 260, in _request
    extract_body, requests_kwargs, post_json)
  File "/srv/homeassistant/lib/python3.5/site-packages/googlemaps/client.py", line 260, in _request
    extract_body, requests_kwargs, post_json)
  File "/srv/homeassistant/lib/python3.5/site-packages/googlemaps/client.py", line 260, in _request
    extract_body, requests_kwargs, post_json)
  File "/srv/homeassistant/lib/python3.5/site-packages/googlemaps/client.py", line 260, in _request
    extract_body, requests_kwargs, post_json)
  File "/srv/homeassistant/lib/python3.5/site-packages/googlemaps/client.py", line 260, in _request
    extract_body, requests_kwargs, post_json)
  File "/srv/homeassistant/lib/python3.5/site-packages/googlemaps/client.py", line 260, in _request
    extract_body, requests_kwargs, post_json)
  File "/srv/homeassistant/lib/python3.5/site-packages/googlemaps/client.py", line 260, in _request
    extract_body, requests_kwargs, post_json)
  File "/srv/homeassistant/lib/python3.5/site-packages/googlemaps/client.py", line 260, in _request
    extract_body, requests_kwargs, post_json)
  File "/srv/homeassistant/lib/python3.5/site-packages/googlemaps/client.py", line 203, in _request
    raise googlemaps.exceptions.Timeout()
googlemaps.exceptions.Timeout
2019-05-24 21:04:43 WARNING (MainThread) [homeassistant.helpers.entity] Update of sensor.to_hannover is taking over 10 seconds
2019-05-24 21:05:04 WARNING (MainThread) [homeassistant.components.sensor] Updating google_travel_time sensor took longer than the scheduled update interval 0:00:30
2019-05-24 21:05:35 WARNING (MainThread) [homeassistant.components.sensor] Updating google_travel_time sensor took longer than the scheduled update interval 0:00:30
2019-05-24 21:05:45 ERROR (MainThread) [homeassistant.helpers.entity] Update for sensor.to_hannover fails
Traceback (most recent call last):
  File "/srv/homeassistant/lib/python3.5/site-packages/googlemaps/client.py", line 253, in _request
    result = self._get_body(response)
  File "/srv/homeassistant/lib/python3.5/site-packages/googlemaps/client.py", line 276, in _get_body
    raise googlemaps.exceptions._RetriableRequest()
googlemaps.exceptions._RetriableRequest

During handling of the above exception, another exception occurred:

Traceback (most recent call last):
  File "/srv/homeassistant/lib/python3.5/site-packages/googlemaps/client.py", line 253, in _request
    result = self._get_body(response)
  File "/srv/homeassistant/lib/python3.5/site-packages/googlemaps/client.py", line 276, in _get_body
    raise googlemaps.exceptions._RetriableRequest()
googlemaps.exceptions._RetriableRequest

During handling of the above exception, another exception occurred:

Traceback (most recent call last):
  File "/srv/homeassistant/lib/python3.5/site-packages/googlemaps/client.py", line 253, in _request
    result = self._get_body(response)
  File "/srv/homeassistant/lib/python3.5/site-packages/googlemaps/client.py", line 276, in _get_body
    raise googlemaps.exceptions._RetriableRequest()
googlemaps.exceptions._RetriableRequest

During handling of the above exception, another exception occurred:

Traceback (most recent call last):
  File "/srv/homeassistant/lib/python3.5/site-packages/googlemaps/client.py", line 253, in _request
    result = self._get_body(response)
  File "/srv/homeassistant/lib/python3.5/site-packages/googlemaps/client.py", line 276, in _get_body
    raise googlemaps.exceptions._RetriableRequest()
googlemaps.exceptions._RetriableRequest

During handling of the above exception, another exception occurred:

Traceback (most recent call last):
  File "/srv/homeassistant/lib/python3.5/site-packages/googlemaps/client.py", line 253, in _request
    result = self._get_body(response)
  File "/srv/homeassistant/lib/python3.5/site-packages/googlemaps/client.py", line 276, in _get_body
    raise googlemaps.exceptions._RetriableRequest()
googlemaps.exceptions._RetriableRequest

During handling of the above exception, another exception occurred:

Traceback (most recent call last):
  File "/srv/homeassistant/lib/python3.5/site-packages/googlemaps/client.py", line 253, in _request
    result = self._get_body(response)
  File "/srv/homeassistant/lib/python3.5/site-packages/googlemaps/client.py", line 276, in _get_body
    raise googlemaps.exceptions._RetriableRequest()
googlemaps.exceptions._RetriableRequest

During handling of the above exception, another exception occurred:

Traceback (most recent call last):
  File "/srv/homeassistant/lib/python3.5/site-packages/googlemaps/client.py", line 253, in _request
    result = self._get_body(response)
  File "/srv/homeassistant/lib/python3.5/site-packages/googlemaps/client.py", line 276, in _get_body
    raise googlemaps.exceptions._RetriableRequest()
googlemaps.exceptions._RetriableRequest

During handling of the above exception, another exception occurred:

Traceback (most recent call last):
  File "/srv/homeassistant/lib/python3.5/site-packages/googlemaps/client.py", line 253, in _request
    result = self._get_body(response)
  File "/srv/homeassistant/lib/python3.5/site-packages/googlemaps/client.py", line 276, in _get_body
    raise googlemaps.exceptions._RetriableRequest()
googlemaps.exceptions._RetriableRequest

During handling of the above exception, another exception occurred:

Traceback (most recent call last):
  File "/srv/homeassistant/lib/python3.5/site-packages/googlemaps/client.py", line 253, in _request
    result = self._get_body(response)
  File "/srv/homeassistant/lib/python3.5/site-packages/googlemaps/client.py", line 276, in _get_body
    raise googlemaps.exceptions._RetriableRequest()
googlemaps.exceptions._RetriableRequest

During handling of the above exception, another exception occurred:

Traceback (most recent call last):
  File "/srv/homeassistant/lib/python3.5/site-packages/googlemaps/client.py", line 253, in _request
    result = self._get_body(response)
  File "/srv/homeassistant/lib/python3.5/site-packages/googlemaps/client.py", line 276, in _get_body
    raise googlemaps.exceptions._RetriableRequest()
googlemaps.exceptions._RetriableRequest

During handling of the above exception, another exception occurred:

Traceback (most recent call last):
  File "/srv/homeassistant/lib/python3.5/site-packages/googlemaps/client.py", line 253, in _request
    result = self._get_body(response)
  File "/srv/homeassistant/lib/python3.5/site-packages/googlemaps/client.py", line 276, in _get_body
    raise googlemaps.exceptions._RetriableRequest()
googlemaps.exceptions._RetriableRequest

During handling of the above exception, another exception occurred:

Traceback (most recent call last):
  File "/srv/homeassistant/lib/python3.5/site-packages/googlemaps/client.py", line 253, in _request
    result = self._get_body(response)
  File "/srv/homeassistant/lib/python3.5/site-packages/googlemaps/client.py", line 276, in _get_body
    raise googlemaps.exceptions._RetriableRequest()
googlemaps.exceptions._RetriableRequest

During handling of the above exception, another exception occurred:

Traceback (most recent call last):
  File "/srv/homeassistant/lib/python3.5/site-packages/homeassistant/helpers/entity.py", line 220, in async_update_ha_state
    await self.async_device_update()
  File "/srv/homeassistant/lib/python3.5/site-packages/homeassistant/helpers/entity.py", line 377, in async_device_update
    await self.hass.async_add_executor_job(self.update)
  File "/usr/lib/python3.5/asyncio/futures.py", line 380, in __iter__
    yield self  # This tells Task to wait for completion.
  File "/usr/lib/python3.5/asyncio/tasks.py", line 304, in _wakeup
    future.result()
  File "/usr/lib/python3.5/asyncio/futures.py", line 293, in result
    raise self._exception
  File "/usr/lib/python3.5/concurrent/futures/thread.py", line 55, in run
    result = self.fn(*self.args, **self.kwargs)
  File "/srv/homeassistant/lib/python3.5/site-packages/homeassistant/util/__init__.py", line 224, in wrapper
    result = method(*args, **kwargs)
  File "/srv/homeassistant/lib/python3.5/site-packages/homeassistant/components/google_travel_time/sensor.py", line 225, in update
    self._origin, self._destination, **options_copy)
  File "/srv/homeassistant/lib/python3.5/site-packages/googlemaps/client.py", line 356, in wrapper
    result = func(*args, **kwargs)
  File "/srv/homeassistant/lib/python3.5/site-packages/googlemaps/distance_matrix.py", line 130, in distance_matrix
    return client._request("/maps/api/distancematrix/json", params)
  File "/srv/homeassistant/lib/python3.5/site-packages/googlemaps/client.py", line 260, in _request
    extract_body, requests_kwargs, post_json)
  File "/srv/homeassistant/lib/python3.5/site-packages/googlemaps/client.py", line 260, in _request
    extract_body, requests_kwargs, post_json)
  File "/srv/homeassistant/lib/python3.5/site-packages/googlemaps/client.py", line 260, in _request
    extract_body, requests_kwargs, post_json)
  File "/srv/homeassistant/lib/python3.5/site-packages/googlemaps/client.py", line 260, in _request
    extract_body, requests_kwargs, post_json)
  File "/srv/homeassistant/lib/python3.5/site-packages/googlemaps/client.py", line 260, in _request
    extract_body, requests_kwargs, post_json)
  File "/srv/homeassistant/lib/python3.5/site-packages/googlemaps/client.py", line 260, in _request
    extract_body, requests_kwargs, post_json)
  File "/srv/homeassistant/lib/python3.5/site-packages/googlemaps/client.py", line 260, in _request
    extract_body, requests_kwargs, post_json)
  File "/srv/homeassistant/lib/python3.5/site-packages/googlemaps/client.py", line 260, in _request
    extract_body, requests_kwargs, post_json)
  File "/srv/homeassistant/lib/python3.5/site-packages/googlemaps/client.py", line 260, in _request
    extract_body, requests_kwargs, post_json)
  File "/srv/homeassistant/lib/python3.5/site-packages/googlemaps/client.py", line 260, in _request
    extract_body, requests_kwargs, post_json)
  File "/srv/homeassistant/lib/python3.5/site-packages/googlemaps/client.py", line 260, in _request
    extract_body, requests_kwargs, post_json)
  File "/srv/homeassistant/lib/python3.5/site-packages/googlemaps/client.py", line 260, in _request
    extract_body, requests_kwargs, post_json)
  File "/srv/homeassistant/lib/python3.5/site-packages/googlemaps/client.py", line 203, in _request
    raise googlemaps.exceptions.Timeout()
googlemaps.exceptions.Timeout
2019-05-24 21:06:16 WARNING (MainThread) [homeassistant.helpers.entity] Update of sensor.to_hannover is taking over 10 seconds
2019-05-24 21:06:37 WARNING (MainThread) [homeassistant.components.sensor] Updating google_travel_time sensor took longer than the scheduled update interval 0:00:30
2019-05-24 21:07:08 WARNING (MainThread) [homeassistant.components.sensor] Updating google_travel_time sensor took longer than the scheduled update interval 0:00:30
2019-05-24 21:07:13 ERROR (MainThread) [homeassistant.helpers.entity] Update for sensor.to_hannover fails
Traceback (most recent call last):
  File "/srv/homeassistant/lib/python3.5/site-packages/googlemaps/client.py", line 253, in _request
    result = self._get_body(response)
  File "/srv/homeassistant/lib/python3.5/site-packages/googlemaps/client.py", line 276, in _get_body
    raise googlemaps.exceptions._RetriableRequest()
googlemaps.exceptions._RetriableRequest

During handling of the above exception, another exception occurred:

Traceback (most recent call last):
  File "/srv/homeassistant/lib/python3.5/site-packages/googlemaps/client.py", line 253, in _request
    result = self._get_body(response)
  File "/srv/homeassistant/lib/python3.5/site-packages/googlemaps/client.py", line 276, in _get_body
    raise googlemaps.exceptions._RetriableRequest()
googlemaps.exceptions._RetriableRequest

During handling of the above exception, another exception occurred:

Traceback (most recent call last):
  File "/srv/homeassistant/lib/python3.5/site-packages/googlemaps/client.py", line 253, in _request
    result = self._get_body(response)
  File "/srv/homeassistant/lib/python3.5/site-packages/googlemaps/client.py", line 276, in _get_body
    raise googlemaps.exceptions._RetriableRequest()
googlemaps.exceptions._RetriableRequest

During handling of the above exception, another exception occurred:

Traceback (most recent call last):
  File "/srv/homeassistant/lib/python3.5/site-packages/googlemaps/client.py", line 253, in _request
    result = self._get_body(response)
  File "/srv/homeassistant/lib/python3.5/site-packages/googlemaps/client.py", line 276, in _get_body
    raise googlemaps.exceptions._RetriableRequest()
googlemaps.exceptions._RetriableRequest

During handling of the above exception, another exception occurred:

Traceback (most recent call last):
  File "/srv/homeassistant/lib/python3.5/site-packages/googlemaps/client.py", line 253, in _request
    result = self._get_body(response)
  File "/srv/homeassistant/lib/python3.5/site-packages/googlemaps/client.py", line 276, in _get_body
    raise googlemaps.exceptions._RetriableRequest()
googlemaps.exceptions._RetriableRequest

During handling of the above exception, another exception occurred:

Traceback (most recent call last):
  File "/srv/homeassistant/lib/python3.5/site-packages/googlemaps/client.py", line 253, in _request
    result = self._get_body(response)
  File "/srv/homeassistant/lib/python3.5/site-packages/googlemaps/client.py", line 276, in _get_body
    raise googlemaps.exceptions._RetriableRequest()
googlemaps.exceptions._RetriableRequest

During handling of the above exception, another exception occurred:

Traceback (most recent call last):
  File "/srv/homeassistant/lib/python3.5/site-packages/googlemaps/client.py", line 253, in _request
    result = self._get_body(response)
  File "/srv/homeassistant/lib/python3.5/site-packages/googlemaps/client.py", line 276, in _get_body
    raise googlemaps.exceptions._RetriableRequest()
googlemaps.exceptions._RetriableRequest

During handling of the above exception, another exception occurred:

Traceback (most recent call last):
  File "/srv/homeassistant/lib/python3.5/site-packages/googlemaps/client.py", line 253, in _request
    result = self._get_body(response)
  File "/srv/homeassistant/lib/python3.5/site-packages/googlemaps/client.py", line 276, in _get_body
    raise googlemaps.exceptions._RetriableRequest()
googlemaps.exceptions._RetriableRequest

During handling of the above exception, another exception occurred:

Traceback (most recent call last):
  File "/srv/homeassistant/lib/python3.5/site-packages/googlemaps/client.py", line 253, in _request
    result = self._get_body(response)
  File "/srv/homeassistant/lib/python3.5/site-packages/googlemaps/client.py", line 276, in _get_body
    raise googlemaps.exceptions._RetriableRequest()
googlemaps.exceptions._RetriableRequest

During handling of the above exception, another exception occurred:

Traceback (most recent call last):
  File "/srv/homeassistant/lib/python3.5/site-packages/googlemaps/client.py", line 253, in _request
    result = self._get_body(response)
  File "/srv/homeassistant/lib/python3.5/site-packages/googlemaps/client.py", line 276, in _get_body
    raise googlemaps.exceptions._RetriableRequest()
googlemaps.exceptions._RetriableRequest

During handling of the above exception, another exception occurred:

Traceback (most recent call last):
  File "/srv/homeassistant/lib/python3.5/site-packages/googlemaps/client.py", line 253, in _request
    result = self._get_body(response)
  File "/srv/homeassistant/lib/python3.5/site-packages/googlemaps/client.py", line 276, in _get_body
    raise googlemaps.exceptions._RetriableRequest()
googlemaps.exceptions._RetriableRequest

During handling of the above exception, another exception occurred:

Traceback (most recent call last):
  File "/srv/homeassistant/lib/python3.5/site-packages/homeassistant/helpers/entity.py", line 220, in async_update_ha_state
    await self.async_device_update()
  File "/srv/homeassistant/lib/python3.5/site-packages/homeassistant/helpers/entity.py", line 377, in async_device_update
    await self.hass.async_add_executor_job(self.update)
  File "/usr/lib/python3.5/asyncio/futures.py", line 380, in __iter__
    yield self  # This tells Task to wait for completion.
  File "/usr/lib/python3.5/asyncio/tasks.py", line 304, in _wakeup
    future.result()
  File "/usr/lib/python3.5/asyncio/futures.py", line 293, in result
    raise self._exception
  File "/usr/lib/python3.5/concurrent/futures/thread.py", line 55, in run
    result = self.fn(*self.args, **self.kwargs)
  File "/srv/homeassistant/lib/python3.5/site-packages/homeassistant/util/__init__.py", line 224, in wrapper
    result = method(*args, **kwargs)
  File "/srv/homeassistant/lib/python3.5/site-packages/homeassistant/components/google_travel_time/sensor.py", line 225, in update
    self._origin, self._destination, **options_copy)
  File "/srv/homeassistant/lib/python3.5/site-packages/googlemaps/client.py", line 356, in wrapper
    result = func(*args, **kwargs)
  File "/srv/homeassistant/lib/python3.5/site-packages/googlemaps/distance_matrix.py", line 130, in distance_matrix
    return client._request("/maps/api/distancematrix/json", params)
  File "/srv/homeassistant/lib/python3.5/site-packages/googlemaps/client.py", line 260, in _request
    extract_body, requests_kwargs, post_json)
  File "/srv/homeassistant/lib/python3.5/site-packages/googlemaps/client.py", line 260, in _request
    extract_body, requests_kwargs, post_json)
  File "/srv/homeassistant/lib/python3.5/site-packages/googlemaps/client.py", line 260, in _request
    extract_body, requests_kwargs, post_json)
  File "/srv/homeassistant/lib/python3.5/site-packages/googlemaps/client.py", line 260, in _request
    extract_body, requests_kwargs, post_json)
  File "/srv/homeassistant/lib/python3.5/site-packages/googlemaps/client.py", line 260, in _request
    extract_body, requests_kwargs, post_json)
  File "/srv/homeassistant/lib/python3.5/site-packages/googlemaps/client.py", line 260, in _request
    extract_body, requests_kwargs, post_json)
  File "/srv/homeassistant/lib/python3.5/site-packages/googlemaps/client.py", line 260, in _request
    extract_body, requests_kwargs, post_json)
  File "/srv/homeassistant/lib/python3.5/site-packages/googlemaps/client.py", line 260, in _request
    extract_body, requests_kwargs, post_json)
  File "/srv/homeassistant/lib/python3.5/site-packages/googlemaps/client.py", line 260, in _request
    extract_body, requests_kwargs, post_json)
  File "/srv/homeassistant/lib/python3.5/site-packages/googlemaps/client.py", line 260, in _request
    extract_body, requests_kwargs, post_json)
  File "/srv/homeassistant/lib/python3.5/site-packages/googlemaps/client.py", line 260, in _request
    extract_body, requests_kwargs, post_json)
  File "/srv/homeassistant/lib/python3.5/site-packages/googlemaps/client.py", line 203, in _request
    raise googlemaps.exceptions.Timeout()
googlemaps.exceptions.Timeout
2019-05-24 21:07:49 WARNING (MainThread) [homeassistant.helpers.entity] Update of sensor.to_hannover is taking over 10 seconds
2019-05-24 21:08:10 WARNING (MainThread) [homeassistant.components.sensor] Updating google_travel_time sensor took longer than the scheduled update interval 0:00:30
2019-05-24 21:08:41 WARNING (MainThread) [homeassistant.components.sensor] Updating google_travel_time sensor took longer than the scheduled update interval 0:00:30
2019-05-24 21:09:12 WARNING (MainThread) [homeassistant.components.sensor] Updating google_travel_time sensor took longer than the scheduled update interval 0:00:30
2019-05-24 21:09:15 ERROR (MainThread) [homeassistant.helpers.entity] Update for sensor.to_hannover fails
Traceback (most recent call last):
  File "/srv/homeassistant/lib/python3.5/site-packages/googlemaps/client.py", line 253, in _request
    result = self._get_body(response)
  File "/srv/homeassistant/lib/python3.5/site-packages/googlemaps/client.py", line 276, in _get_body
    raise googlemaps.exceptions._RetriableRequest()
googlemaps.exceptions._RetriableRequest

During handling of the above exception, another exception occurred:

Traceback (most recent call last):
  File "/srv/homeassistant/lib/python3.5/site-packages/googlemaps/client.py", line 253, in _request
    result = self._get_body(response)
  File "/srv/homeassistant/lib/python3.5/site-packages/googlemaps/client.py", line 276, in _get_body
    raise googlemaps.exceptions._RetriableRequest()
googlemaps.exceptions._RetriableRequest

During handling of the above exception, another exception occurred:

Traceback (most recent call last):
  File "/srv/homeassistant/lib/python3.5/site-packages/googlemaps/client.py", line 253, in _request
    result = self._get_body(response)
  File "/srv/homeassistant/lib/python3.5/site-packages/googlemaps/client.py", line 276, in _get_body
    raise googlemaps.exceptions._RetriableRequest()
googlemaps.exceptions._RetriableRequest

During handling of the above exception, another exception occurred:

Traceback (most recent call last):
  File "/srv/homeassistant/lib/python3.5/site-packages/googlemaps/client.py", line 253, in _request
    result = self._get_body(response)
  File "/srv/homeassistant/lib/python3.5/site-packages/googlemaps/client.py", line 276, in _get_body
    raise googlemaps.exceptions._RetriableRequest()
googlemaps.exceptions._RetriableRequest

During handling of the above exception, another exception occurred:

Traceback (most recent call last):
  File "/srv/homeassistant/lib/python3.5/site-packages/googlemaps/client.py", line 253, in _request
    result = self._get_body(response)
  File "/srv/homeassistant/lib/python3.5/site-packages/googlemaps/client.py", line 276, in _get_body
    raise googlemaps.exceptions._RetriableRequest()
googlemaps.exceptions._RetriableRequest

During handling of the above exception, another exception occurred:

Traceback (most recent call last):
  File "/srv/homeassistant/lib/python3.5/site-packages/googlemaps/client.py", line 253, in _request
    result = self._get_body(response)
  File "/srv/homeassistant/lib/python3.5/site-packages/googlemaps/client.py", line 276, in _get_body
    raise googlemaps.exceptions._RetriableRequest()
googlemaps.exceptions._RetriableRequest

During handling of the above exception, another exception occurred:

Traceback (most recent call last):
  File "/srv/homeassistant/lib/python3.5/site-packages/googlemaps/client.py", line 253, in _request
    result = self._get_body(response)
  File "/srv/homeassistant/lib/python3.5/site-packages/googlemaps/client.py", line 276, in _get_body
    raise googlemaps.exceptions._RetriableRequest()
googlemaps.exceptions._RetriableRequest

During handling of the above exception, another exception occurred:

Traceback (most recent call last):
  File "/srv/homeassistant/lib/python3.5/site-packages/googlemaps/client.py", line 253, in _request
    result = self._get_body(response)
  File "/srv/homeassistant/lib/python3.5/site-packages/googlemaps/client.py", line 276, in _get_body
    raise googlemaps.exceptions._RetriableRequest()
googlemaps.exceptions._RetriableRequest

During handling of the above exception, another exception occurred:

Traceback (most recent call last):
  File "/srv/homeassistant/lib/python3.5/site-packages/googlemaps/client.py", line 253, in _request
    result = self._get_body(response)
  File "/srv/homeassistant/lib/python3.5/site-packages/googlemaps/client.py", line 276, in _get_body
    raise googlemaps.exceptions._RetriableRequest()
googlemaps.exceptions._RetriableRequest

During handling of the above exception, another exception occurred:

Traceback (most recent call last):
  File "/srv/homeassistant/lib/python3.5/site-packages/googlemaps/client.py", line 253, in _request
    result = self._get_body(response)
  File "/srv/homeassistant/lib/python3.5/site-packages/googlemaps/client.py", line 276, in _get_body
    raise googlemaps.exceptions._RetriableRequest()
googlemaps.exceptions._RetriableRequest

During handling of the above exception, another exception occurred:

Traceback (most recent call last):
  File "/srv/homeassistant/lib/python3.5/site-packages/googlemaps/client.py", line 253, in _request
    result = self._get_body(response)
  File "/srv/homeassistant/lib/python3.5/site-packages/googlemaps/client.py", line 276, in _get_body
    raise googlemaps.exceptions._RetriableRequest()
googlemaps.exceptions._RetriableRequest

During handling of the above exception, another exception occurred:

Traceback (most recent call last):
  File "/srv/homeassistant/lib/python3.5/site-packages/googlemaps/client.py", line 253, in _request
    result = self._get_body(response)
  File "/srv/homeassistant/lib/python3.5/site-packages/googlemaps/client.py", line 276, in _get_body
    raise googlemaps.exceptions._RetriableRequest()
googlemaps.exceptions._RetriableRequest

During handling of the above exception, another exception occurred:

Traceback (most recent call last):
  File "/srv/homeassistant/lib/python3.5/site-packages/homeassistant/helpers/entity.py", line 220, in async_update_ha_state
    await self.async_device_update()
  File "/srv/homeassistant/lib/python3.5/site-packages/homeassistant/helpers/entity.py", line 377, in async_device_update
    await self.hass.async_add_executor_job(self.update)
  File "/usr/lib/python3.5/asyncio/futures.py", line 380, in __iter__
    yield self  # This tells Task to wait for completion.
  File "/usr/lib/python3.5/asyncio/tasks.py", line 304, in _wakeup
    future.result()
  File "/usr/lib/python3.5/asyncio/futures.py", line 293, in result
    raise self._exception
  File "/usr/lib/python3.5/concurrent/futures/thread.py", line 55, in run
    result = self.fn(*self.args, **self.kwargs)
  File "/srv/homeassistant/lib/python3.5/site-packages/homeassistant/util/__init__.py", line 224, in wrapper
    result = method(*args, **kwargs)
  File "/srv/homeassistant/lib/python3.5/site-packages/homeassistant/components/google_travel_time/sensor.py", line 225, in update
    self._origin, self._destination, **options_copy)
  File "/srv/homeassistant/lib/python3.5/site-packages/googlemaps/client.py", line 356, in wrapper
    result = func(*args, **kwargs)
  File "/srv/homeassistant/lib/python3.5/site-packages/googlemaps/distance_matrix.py", line 130, in distance_matrix
    return client._request("/maps/api/distancematrix/json", params)
  File "/srv/homeassistant/lib/python3.5/site-packages/googlemaps/client.py", line 260, in _request
    extract_body, requests_kwargs, post_json)
  File "/srv/homeassistant/lib/python3.5/site-packages/googlemaps/client.py", line 260, in _request
    extract_body, requests_kwargs, post_json)
  File "/srv/homeassistant/lib/python3.5/site-packages/googlemaps/client.py", line 260, in _request
    extract_body, requests_kwargs, post_json)
  File "/srv/homeassistant/lib/python3.5/site-packages/googlemaps/client.py", line 260, in _request
    extract_body, requests_kwargs, post_json)
  File "/srv/homeassistant/lib/python3.5/site-packages/googlemaps/client.py", line 260, in _request
    extract_body, requests_kwargs, post_json)
  File "/srv/homeassistant/lib/python3.5/site-packages/googlemaps/client.py", line 260, in _request
    extract_body, requests_kwargs, post_json)
  File "/srv/homeassistant/lib/python3.5/site-packages/googlemaps/client.py", line 260, in _request
    extract_body, requests_kwargs, post_json)
  File "/srv/homeassistant/lib/python3.5/site-packages/googlemaps/client.py", line 260, in _request
    extract_body, requests_kwargs, post_json)
  File "/srv/homeassistant/lib/python3.5/site-packages/googlemaps/client.py", line 260, in _request
    extract_body, requests_kwargs, post_json)
  File "/srv/homeassistant/lib/python3.5/site-packages/googlemaps/client.py", line 260, in _request
    extract_body, requests_kwargs, post_json)
  File "/srv/homeassistant/lib/python3.5/site-packages/googlemaps/client.py", line 260, in _request
    extract_body, requests_kwargs, post_json)
  File "/srv/homeassistant/lib/python3.5/site-packages/googlemaps/client.py", line 260, in _request
    extract_body, requests_kwargs, post_json)
  File "/srv/homeassistant/lib/python3.5/site-packages/googlemaps/client.py", line 203, in _request
    raise googlemaps.exceptions.Timeout()
googlemaps.exceptions.Timeout
2019-05-24 21:09:53 WARNING (MainThread) [homeassistant.helpers.entity] Update of sensor.to_hannover is taking over 10 seconds
2019-05-24 21:10:14 WARNING (MainThread) [homeassistant.components.sensor] Updating google_travel_time sensor took longer than the scheduled update interval 0:00:30
2019-05-24 21:10:45 WARNING (MainThread) [homeassistant.components.sensor] Updating google_travel_time sensor took longer than the scheduled update interval 0:00:30
2019-05-24 21:11:10 ERROR (MainThread) [homeassistant.helpers.entity] Update for sensor.to_hannover fails
Traceback (most recent call last):
  File "/srv/homeassistant/lib/python3.5/site-packages/googlemaps/client.py", line 253, in _request
    result = self._get_body(response)
  File "/srv/homeassistant/lib/python3.5/site-packages/googlemaps/client.py", line 276, in _get_body
    raise googlemaps.exceptions._RetriableRequest()
googlemaps.exceptions._RetriableRequest

During handling of the above exception, another exception occurred:

Traceback (most recent call last):
  File "/srv/homeassistant/lib/python3.5/site-packages/googlemaps/client.py", line 253, in _request
    result = self._get_body(response)
  File "/srv/homeassistant/lib/python3.5/site-packages/googlemaps/client.py", line 276, in _get_body
    raise googlemaps.exceptions._RetriableRequest()
googlemaps.exceptions._RetriableRequest

During handling of the above exception, another exception occurred:

Traceback (most recent call last):
  File "/srv/homeassistant/lib/python3.5/site-packages/googlemaps/client.py", line 253, in _request
    result = self._get_body(response)
  File "/srv/homeassistant/lib/python3.5/site-packages/googlemaps/client.py", line 276, in _get_body
    raise googlemaps.exceptions._RetriableRequest()
googlemaps.exceptions._RetriableRequest

During handling of the above exception, another exception occurred:

Traceback (most recent call last):
  File "/srv/homeassistant/lib/python3.5/site-packages/googlemaps/client.py", line 253, in _request
    result = self._get_body(response)
  File "/srv/homeassistant/lib/python3.5/site-packages/googlemaps/client.py", line 276, in _get_body
    raise googlemaps.exceptions._RetriableRequest()
googlemaps.exceptions._RetriableRequest

During handling of the above exception, another exception occurred:

Traceback (most recent call last):
  File "/srv/homeassistant/lib/python3.5/site-packages/googlemaps/client.py", line 253, in _request
    result = self._get_body(response)
  File "/srv/homeassistant/lib/python3.5/site-packages/googlemaps/client.py", line 276, in _get_body
    raise googlemaps.exceptions._RetriableRequest()
googlemaps.exceptions._RetriableRequest

During handling of the above exception, another exception occurred:

Traceback (most recent call last):
  File "/srv/homeassistant/lib/python3.5/site-packages/googlemaps/client.py", line 253, in _request
    result = self._get_body(response)
  File "/srv/homeassistant/lib/python3.5/site-packages/googlemaps/client.py", line 276, in _get_body
    raise googlemaps.exceptions._RetriableRequest()
googlemaps.exceptions._RetriableRequest

During handling of the above exception, another exception occurred:

Traceback (most recent call last):
  File "/srv/homeassistant/lib/python3.5/site-packages/googlemaps/client.py", line 253, in _request
    result = self._get_body(response)
  File "/srv/homeassistant/lib/python3.5/site-packages/googlemaps/client.py", line 276, in _get_body
    raise googlemaps.exceptions._RetriableRequest()
googlemaps.exceptions._RetriableRequest

During handling of the above exception, another exception occurred:

Traceback (most recent call last):
  File "/srv/homeassistant/lib/python3.5/site-packages/googlemaps/client.py", line 253, in _request
    result = self._get_body(response)
  File "/srv/homeassistant/lib/python3.5/site-packages/googlemaps/client.py", line 276, in _get_body
    raise googlemaps.exceptions._RetriableRequest()
googlemaps.exceptions._RetriableRequest

During handling of the above exception, another exception occurred:

Traceback (most recent call last):
  File "/srv/homeassistant/lib/python3.5/site-packages/googlemaps/client.py", line 253, in _request
    result = self._get_body(response)
  File "/srv/homeassistant/lib/python3.5/site-packages/googlemaps/client.py", line 276, in _get_body
    raise googlemaps.exceptions._RetriableRequest()
googlemaps.exceptions._RetriableRequest

During handling of the above exception, another exception occurred:

Traceback (most recent call last):
  File "/srv/homeassistant/lib/python3.5/site-packages/googlemaps/client.py", line 253, in _request
    result = self._get_body(response)
  File "/srv/homeassistant/lib/python3.5/site-packages/googlemaps/client.py", line 276, in _get_body
    raise googlemaps.exceptions._RetriableRequest()
googlemaps.exceptions._RetriableRequest

During handling of the above exception, another exception occurred:

Traceback (most recent call last):
  File "/srv/homeassistant/lib/python3.5/site-packages/googlemaps/client.py", line 253, in _request
    result = self._get_body(response)
  File "/srv/homeassistant/lib/python3.5/site-packages/googlemaps/client.py", line 276, in _get_body
    raise googlemaps.exceptions._RetriableRequest()
googlemaps.exceptions._RetriableRequest

During handling of the above exception, another exception occurred:

Traceback (most recent call last):
  File "/srv/homeassistant/lib/python3.5/site-packages/googlemaps/client.py", line 253, in _request
    result = self._get_body(response)
  File "/srv/homeassistant/lib/python3.5/site-packages/googlemaps/client.py", line 276, in _get_body
    raise googlemaps.exceptions._RetriableRequest()
googlemaps.exceptions._RetriableRequest

During handling of the above exception, another exception occurred:

Traceback (most recent call last):
  File "/srv/homeassistant/lib/python3.5/site-packages/homeassistant/helpers/entity.py", line 220, in async_update_ha_state
    await self.async_device_update()
  File "/srv/homeassistant/lib/python3.5/site-packages/homeassistant/helpers/entity.py", line 377, in async_device_update
    await self.hass.async_add_executor_job(self.update)
  File "/usr/lib/python3.5/asyncio/futures.py", line 380, in __iter__
    yield self  # This tells Task to wait for completion.
  File "/usr/lib/python3.5/asyncio/tasks.py", line 304, in _wakeup
    future.result()
  File "/usr/lib/python3.5/asyncio/futures.py", line 293, in result
    raise self._exception
  File "/usr/lib/python3.5/concurrent/futures/thread.py", line 55, in run
    result = self.fn(*self.args, **self.kwargs)
  File "/srv/homeassistant/lib/python3.5/site-packages/homeassistant/util/__init__.py", line 224, in wrapper
    result = method(*args, **kwargs)
  File "/srv/homeassistant/lib/python3.5/site-packages/homeassistant/components/google_travel_time/sensor.py", line 225, in update
    self._origin, self._destination, **options_copy)
  File "/srv/homeassistant/lib/python3.5/site-packages/googlemaps/client.py", line 356, in wrapper
    result = func(*args, **kwargs)
  File "/srv/homeassistant/lib/python3.5/site-packages/googlemaps/distance_matrix.py", line 130, in distance_matrix
    return client._request("/maps/api/distancematrix/json", params)
  File "/srv/homeassistant/lib/python3.5/site-packages/googlemaps/client.py", line 260, in _request
    extract_body, requests_kwargs, post_json)
  File "/srv/homeassistant/lib/python3.5/site-packages/googlemaps/client.py", line 260, in _request
    extract_body, requests_kwargs, post_json)
  File "/srv/homeassistant/lib/python3.5/site-packages/googlemaps/client.py", line 260, in _request
    extract_body, requests_kwargs, post_json)
  File "/srv/homeassistant/lib/python3.5/site-packages/googlemaps/client.py", line 260, in _request
    extract_body, requests_kwargs, post_json)
  File "/srv/homeassistant/lib/python3.5/site-packages/googlemaps/client.py", line 260, in _request
    extract_body, requests_kwargs, post_json)
  File "/srv/homeassistant/lib/python3.5/site-packages/googlemaps/client.py", line 260, in _request
    extract_body, requests_kwargs, post_json)
  File "/srv/homeassistant/lib/python3.5/site-packages/googlemaps/client.py", line 260, in _request
    extract_body, requests_kwargs, post_json)
  File "/srv/homeassistant/lib/python3.5/site-packages/googlemaps/client.py", line 260, in _request
    extract_body, requests_kwargs, post_json)
  File "/srv/homeassistant/lib/python3.5/site-packages/googlemaps/client.py", line 260, in _request
    extract_body, requests_kwargs, post_json)
  File "/srv/homeassistant/lib/python3.5/site-packages/googlemaps/client.py", line 260, in _request
    extract_body, requests_kwargs, post_json)
  File "/srv/homeassistant/lib/python3.5/site-packages/googlemaps/client.py", line 260, in _request
    extract_body, requests_kwargs, post_json)
  File "/srv/homeassistant/lib/python3.5/site-packages/googlemaps/client.py", line 260, in _request
    extract_body, requests_kwargs, post_json)
  File "/srv/homeassistant/lib/python3.5/site-packages/googlemaps/client.py", line 203, in _request
    raise googlemaps.exceptions.Timeout()
googlemaps.exceptions.Timeout
2019-05-24 21:11:26 WARNING (MainThread) [homeassistant.helpers.entity] Update of sensor.to_hannover is taking over 10 seconds
2019-05-24 21:11:47 WARNING (MainThread) [homeassistant.components.sensor] Updating google_travel_time sensor took longer than the scheduled update interval 0:00:30
2019-05-24 21:12:18 WARNING (MainThread) [homeassistant.components.sensor] Updating google_travel_time sensor took longer than the scheduled update interval 0:00:30
2019-05-24 21:12:26 ERROR (MainThread) [homeassistant.helpers.entity] Update for sensor.to_hannover fails
Traceback (most recent call last):
  File "/srv/homeassistant/lib/python3.5/site-packages/googlemaps/client.py", line 253, in _request
    result = self._get_body(response)
  File "/srv/homeassistant/lib/python3.5/site-packages/googlemaps/client.py", line 276, in _get_body
    raise googlemaps.exceptions._RetriableRequest()
googlemaps.exceptions._RetriableRequest

During handling of the above exception, another exception occurred:

Traceback (most recent call last):
  File "/srv/homeassistant/lib/python3.5/site-packages/googlemaps/client.py", line 253, in _request
    result = self._get_body(response)
  File "/srv/homeassistant/lib/python3.5/site-packages/googlemaps/client.py", line 276, in _get_body
    raise googlemaps.exceptions._RetriableRequest()
googlemaps.exceptions._RetriableRequest

During handling of the above exception, another exception occurred:

Traceback (most recent call last):
  File "/srv/homeassistant/lib/python3.5/site-packages/googlemaps/client.py", line 253, in _request
    result = self._get_body(response)
  File "/srv/homeassistant/lib/python3.5/site-packages/googlemaps/client.py", line 276, in _get_body
    raise googlemaps.exceptions._RetriableRequest()
googlemaps.exceptions._RetriableRequest

During handling of the above exception, another exception occurred:

Traceback (most recent call last):
  File "/srv/homeassistant/lib/python3.5/site-packages/googlemaps/client.py", line 253, in _request
    result = self._get_body(response)
  File "/srv/homeassistant/lib/python3.5/site-packages/googlemaps/client.py", line 276, in _get_body
    raise googlemaps.exceptions._RetriableRequest()
googlemaps.exceptions._RetriableRequest

During handling of the above exception, another exception occurred:

Traceback (most recent call last):
  File "/srv/homeassistant/lib/python3.5/site-packages/googlemaps/client.py", line 253, in _request
    result = self._get_body(response)
  File "/srv/homeassistant/lib/python3.5/site-packages/googlemaps/client.py", line 276, in _get_body
    raise googlemaps.exceptions._RetriableRequest()
googlemaps.exceptions._RetriableRequest

During handling of the above exception, another exception occurred:

Traceback (most recent call last):
  File "/srv/homeassistant/lib/python3.5/site-packages/googlemaps/client.py", line 253, in _request
    result = self._get_body(response)
  File "/srv/homeassistant/lib/python3.5/site-packages/googlemaps/client.py", line 276, in _get_body
    raise googlemaps.exceptions._RetriableRequest()
googlemaps.exceptions._RetriableRequest

During handling of the above exception, another exception occurred:

Traceback (most recent call last):
  File "/srv/homeassistant/lib/python3.5/site-packages/googlemaps/client.py", line 253, in _request
    result = self._get_body(response)
  File "/srv/homeassistant/lib/python3.5/site-packages/googlemaps/client.py", line 276, in _get_body
    raise googlemaps.exceptions._RetriableRequest()
googlemaps.exceptions._RetriableRequest

During handling of the above exception, another exception occurred:

Traceback (most recent call last):
  File "/srv/homeassistant/lib/python3.5/site-packages/googlemaps/client.py", line 253, in _request
    result = self._get_body(response)
  File "/srv/homeassistant/lib/python3.5/site-packages/googlemaps/client.py", line 276, in _get_body
    raise googlemaps.exceptions._RetriableRequest()
googlemaps.exceptions._RetriableRequest

During handling of the above exception, another exception occurred:

Traceback (most recent call last):
  File "/srv/homeassistant/lib/python3.5/site-packages/googlemaps/client.py", line 253, in _request
    result = self._get_body(response)
  File "/srv/homeassistant/lib/python3.5/site-packages/googlemaps/client.py", line 276, in _get_body
    raise googlemaps.exceptions._RetriableRequest()
googlemaps.exceptions._RetriableRequest

During handling of the above exception, another exception occurred:

Traceback (most recent call last):
  File "/srv/homeassistant/lib/python3.5/site-packages/googlemaps/client.py", line 253, in _request
    result = self._get_body(response)
  File "/srv/homeassistant/lib/python3.5/site-packages/googlemaps/client.py", line 276, in _get_body
    raise googlemaps.exceptions._RetriableRequest()
googlemaps.exceptions._RetriableRequest

During handling of the above exception, another exception occurred:

Traceback (most recent call last):
  File "/srv/homeassistant/lib/python3.5/site-packages/googlemaps/client.py", line 253, in _request
    result = self._get_body(response)
  File "/srv/homeassistant/lib/python3.5/site-packages/googlemaps/client.py", line 276, in _get_body
    raise googlemaps.exceptions._RetriableRequest()
googlemaps.exceptions._RetriableRequest

During handling of the above exception, another exception occurred:

Traceback (most recent call last):
  File "/srv/homeassistant/lib/python3.5/site-packages/homeassistant/helpers/entity.py", line 220, in async_update_ha_state
    await self.async_device_update()
  File "/srv/homeassistant/lib/python3.5/site-packages/homeassistant/helpers/entity.py", line 377, in async_device_update
    await self.hass.async_add_executor_job(self.update)
  File "/usr/lib/python3.5/asyncio/futures.py", line 380, in __iter__
    yield self  # This tells Task to wait for completion.
  File "/usr/lib/python3.5/asyncio/tasks.py", line 304, in _wakeup
    future.result()
  File "/usr/lib/python3.5/asyncio/futures.py", line 293, in result
    raise self._exception
  File "/usr/lib/python3.5/concurrent/futures/thread.py", line 55, in run
    result = self.fn(*self.args, **self.kwargs)
  File "/srv/homeassistant/lib/python3.5/site-packages/homeassistant/util/__init__.py", line 224, in wrapper
    result = method(*args, **kwargs)
  File "/srv/homeassistant/lib/python3.5/site-packages/homeassistant/components/google_travel_time/sensor.py", line 225, in update
    self._origin, self._destination, **options_copy)
  File "/srv/homeassistant/lib/python3.5/site-packages/googlemaps/client.py", line 356, in wrapper
    result = func(*args, **kwargs)
  File "/srv/homeassistant/lib/python3.5/site-packages/googlemaps/distance_matrix.py", line 130, in distance_matrix
    return client._request("/maps/api/distancematrix/json", params)
  File "/srv/homeassistant/lib/python3.5/site-packages/googlemaps/client.py", line 260, in _request
    extract_body, requests_kwargs, post_json)
  File "/srv/homeassistant/lib/python3.5/site-packages/googlemaps/client.py", line 260, in _request
    extract_body, requests_kwargs, post_json)
  File "/srv/homeassistant/lib/python3.5/site-packages/googlemaps/client.py", line 260, in _request
    extract_body, requests_kwargs, post_json)
  File "/srv/homeassistant/lib/python3.5/site-packages/googlemaps/client.py", line 260, in _request
    extract_body, requests_kwargs, post_json)
  File "/srv/homeassistant/lib/python3.5/site-packages/googlemaps/client.py", line 260, in _request
    extract_body, requests_kwargs, post_json)
  File "/srv/homeassistant/lib/python3.5/site-packages/googlemaps/client.py", line 260, in _request
    extract_body, requests_kwargs, post_json)
  File "/srv/homeassistant/lib/python3.5/site-packages/googlemaps/client.py", line 260, in _request
    extract_body, requests_kwargs, post_json)
  File "/srv/homeassistant/lib/python3.5/site-packages/googlemaps/client.py", line 260, in _request
    extract_body, requests_kwargs, post_json)
  File "/srv/homeassistant/lib/python3.5/site-packages/googlemaps/client.py", line 260, in _request
    extract_body, requests_kwargs, post_json)
  File "/srv/homeassistant/lib/python3.5/site-packages/googlemaps/client.py", line 260, in _request
    extract_body, requests_kwargs, post_json)
  File "/srv/homeassistant/lib/python3.5/site-packages/googlemaps/client.py", line 260, in _request
    extract_body, requests_kwargs, post_json)
  File "/srv/homeassistant/lib/python3.5/site-packages/googlemaps/client.py", line 203, in _request
    raise googlemaps.exceptions.Timeout()
googlemaps.exceptions.Timeout
2019-05-24 21:12:59 WARNING (MainThread) [homeassistant.helpers.entity] Update of sensor.to_hannover is taking over 10 seconds
2019-05-24 21:13:20 WARNING (MainThread) [homeassistant.components.sensor] Updating google_travel_time sensor took longer than the scheduled update interval 0:00:30
2019-05-24 21:13:51 WARNING (MainThread) [homeassistant.components.sensor] Updating google_travel_time sensor took longer than the scheduled update interval 0:00:30
2019-05-24 21:14:11 ERROR (MainThread) [homeassistant.helpers.entity] Update for sensor.to_hannover fails
Traceback (most recent call last):
  File "/srv/homeassistant/lib/python3.5/site-packages/googlemaps/client.py", line 253, in _request
    result = self._get_body(response)
  File "/srv/homeassistant/lib/python3.5/site-packages/googlemaps/client.py", line 276, in _get_body
    raise googlemaps.exceptions._RetriableRequest()
googlemaps.exceptions._RetriableRequest

During handling of the above exception, another exception occurred:

Traceback (most recent call last):
  File "/srv/homeassistant/lib/python3.5/site-packages/googlemaps/client.py", line 253, in _request
    result = self._get_body(response)
  File "/srv/homeassistant/lib/python3.5/site-packages/googlemaps/client.py", line 276, in _get_body
    raise googlemaps.exceptions._RetriableRequest()
googlemaps.exceptions._RetriableRequest

During handling of the above exception, another exception occurred:

Traceback (most recent call last):
  File "/srv/homeassistant/lib/python3.5/site-packages/googlemaps/client.py", line 253, in _request
    result = self._get_body(response)
  File "/srv/homeassistant/lib/python3.5/site-packages/googlemaps/client.py", line 276, in _get_body
    raise googlemaps.exceptions._RetriableRequest()
googlemaps.exceptions._RetriableRequest

During handling of the above exception, another exception occurred:

Traceback (most recent call last):
  File "/srv/homeassistant/lib/python3.5/site-packages/googlemaps/client.py", line 253, in _request
    result = self._get_body(response)
  File "/srv/homeassistant/lib/python3.5/site-packages/googlemaps/client.py", line 276, in _get_body
    raise googlemaps.exceptions._RetriableRequest()
googlemaps.exceptions._RetriableRequest

During handling of the above exception, another exception occurred:

Traceback (most recent call last):
  File "/srv/homeassistant/lib/python3.5/site-packages/googlemaps/client.py", line 253, in _request
    result = self._get_body(response)
  File "/srv/homeassistant/lib/python3.5/site-packages/googlemaps/client.py", line 276, in _get_body
    raise googlemaps.exceptions._RetriableRequest()
googlemaps.exceptions._RetriableRequest

During handling of the above exception, another exception occurred:

Traceback (most recent call last):
  File "/srv/homeassistant/lib/python3.5/site-packages/googlemaps/client.py", line 253, in _request
    result = self._get_body(response)
  File "/srv/homeassistant/lib/python3.5/site-packages/googlemaps/client.py", line 276, in _get_body
    raise googlemaps.exceptions._RetriableRequest()
googlemaps.exceptions._RetriableRequest

During handling of the above exception, another exception occurred:

Traceback (most recent call last):
  File "/srv/homeassistant/lib/python3.5/site-packages/googlemaps/client.py", line 253, in _request
    result = self._get_body(response)
  File "/srv/homeassistant/lib/python3.5/site-packages/googlemaps/client.py", line 276, in _get_body
    raise googlemaps.exceptions._RetriableRequest()
googlemaps.exceptions._RetriableRequest

During handling of the above exception, another exception occurred:

Traceback (most recent call last):
  File "/srv/homeassistant/lib/python3.5/site-packages/googlemaps/client.py", line 253, in _request
    result = self._get_body(response)
  File "/srv/homeassistant/lib/python3.5/site-packages/googlemaps/client.py", line 276, in _get_body
    raise googlemaps.exceptions._RetriableRequest()
googlemaps.exceptions._RetriableRequest

During handling of the above exception, another exception occurred:

Traceback (most recent call last):
  File "/srv/homeassistant/lib/python3.5/site-packages/googlemaps/client.py", line 253, in _request
    result = self._get_body(response)
  File "/srv/homeassistant/lib/python3.5/site-packages/googlemaps/client.py", line 276, in _get_body
    raise googlemaps.exceptions._RetriableRequest()
googlemaps.exceptions._RetriableRequest

During handling of the above exception, another exception occurred:

Traceback (most recent call last):
  File "/srv/homeassistant/lib/python3.5/site-packages/googlemaps/client.py", line 253, in _request
    result = self._get_body(response)
  File "/srv/homeassistant/lib/python3.5/site-packages/googlemaps/client.py", line 276, in _get_body
    raise googlemaps.exceptions._RetriableRequest()
googlemaps.exceptions._RetriableRequest

During handling of the above exception, another exception occurred:

Traceback (most recent call last):
  File "/srv/homeassistant/lib/python3.5/site-packages/googlemaps/client.py", line 253, in _request
    result = self._get_body(response)
  File "/srv/homeassistant/lib/python3.5/site-packages/googlemaps/client.py", line 276, in _get_body
    raise googlemaps.exceptions._RetriableRequest()
googlemaps.exceptions._RetriableRequest

During handling of the above exception, another exception occurred:

Traceback (most recent call last):
  File "/srv/homeassistant/lib/python3.5/site-packages/googlemaps/client.py", line 253, in _request
    result = self._get_body(response)
  File "/srv/homeassistant/lib/python3.5/site-packages/googlemaps/client.py", line 276, in _get_body
    raise googlemaps.exceptions._RetriableRequest()
googlemaps.exceptions._RetriableRequest

During handling of the above exception, another exception occurred:

Traceback (most recent call last):
  File "/srv/homeassistant/lib/python3.5/site-packages/homeassistant/helpers/entity.py", line 220, in async_update_ha_state
    await self.async_device_update()
  File "/srv/homeassistant/lib/python3.5/site-packages/homeassistant/helpers/entity.py", line 377, in async_device_update
    await self.hass.async_add_executor_job(self.update)
  File "/usr/lib/python3.5/asyncio/futures.py", line 380, in __iter__
    yield self  # This tells Task to wait for completion.
  File "/usr/lib/python3.5/asyncio/tasks.py", line 304, in _wakeup
    future.result()
  File "/usr/lib/python3.5/asyncio/futures.py", line 293, in result
    raise self._exception
  File "/usr/lib/python3.5/concurrent/futures/thread.py", line 55, in run
    result = self.fn(*self.args, **self.kwargs)
  File "/srv/homeassistant/lib/python3.5/site-packages/homeassistant/util/__init__.py", line 224, in wrapper
    result = method(*args, **kwargs)
  File "/srv/homeassistant/lib/python3.5/site-packages/homeassistant/components/google_travel_time/sensor.py", line 225, in update
    self._origin, self._destination, **options_copy)
  File "/srv/homeassistant/lib/python3.5/site-packages/googlemaps/client.py", line 356, in wrapper
    result = func(*args, **kwargs)
  File "/srv/homeassistant/lib/python3.5/site-packages/googlemaps/distance_matrix.py", line 130, in distance_matrix
    return client._request("/maps/api/distancematrix/json", params)
  File "/srv/homeassistant/lib/python3.5/site-packages/googlemaps/client.py", line 260, in _request
    extract_body, requests_kwargs, post_json)
  File "/srv/homeassistant/lib/python3.5/site-packages/googlemaps/client.py", line 260, in _request
    extract_body, requests_kwargs, post_json)
  File "/srv/homeassistant/lib/python3.5/site-packages/googlemaps/client.py", line 260, in _request
    extract_body, requests_kwargs, post_json)
  File "/srv/homeassistant/lib/python3.5/site-packages/googlemaps/client.py", line 260, in _request
    extract_body, requests_kwargs, post_json)
  File "/srv/homeassistant/lib/python3.5/site-packages/googlemaps/client.py", line 260, in _request
    extract_body, requests_kwargs, post_json)
  File "/srv/homeassistant/lib/python3.5/site-packages/googlemaps/client.py", line 260, in _request
    extract_body, requests_kwargs, post_json)
  File "/srv/homeassistant/lib/python3.5/site-packages/googlemaps/client.py", line 260, in _request
    extract_body, requests_kwargs, post_json)
  File "/srv/homeassistant/lib/python3.5/site-packages/googlemaps/client.py", line 260, in _request
    extract_body, requests_kwargs, post_json)
  File "/srv/homeassistant/lib/python3.5/site-packages/googlemaps/client.py", line 260, in _request
    extract_body, requests_kwargs, post_json)
  File "/srv/homeassistant/lib/python3.5/site-packages/googlemaps/client.py", line 260, in _request
    extract_body, requests_kwargs, post_json)
  File "/srv/homeassistant/lib/python3.5/site-packages/googlemaps/client.py", line 260, in _request
    extract_body, requests_kwargs, post_json)
  File "/srv/homeassistant/lib/python3.5/site-packages/googlemaps/client.py", line 260, in _request
    extract_body, requests_kwargs, post_json)
  File "/srv/homeassistant/lib/python3.5/site-packages/googlemaps/client.py", line 203, in _request
    raise googlemaps.exceptions.Timeout()
googlemaps.exceptions.Timeout
2019-05-24 21:14:32 WARNING (MainThread) [homeassistant.helpers.entity] Update of sensor.to_hannover is taking over 10 seconds
2019-05-24 21:14:53 WARNING (MainThread) [homeassistant.components.sensor] Updating google_travel_time sensor took longer than the scheduled update interval 0:00:30
2019-05-24 21:15:24 WARNING (MainThread) [homeassistant.components.sensor] Updating google_travel_time sensor took longer than the scheduled update interval 0:00:30
2019-05-24 21:15:48 ERROR (MainThread) [homeassistant.helpers.entity] Update for sensor.to_hannover fails
Traceback (most recent call last):
  File "/srv/homeassistant/lib/python3.5/site-packages/googlemaps/client.py", line 253, in _request
    result = self._get_body(response)
  File "/srv/homeassistant/lib/python3.5/site-packages/googlemaps/client.py", line 276, in _get_body
    raise googlemaps.exceptions._RetriableRequest()
googlemaps.exceptions._RetriableRequest

During handling of the above exception, another exception occurred:

Traceback (most recent call last):
  File "/srv/homeassistant/lib/python3.5/site-packages/googlemaps/client.py", line 253, in _request
    result = self._get_body(response)
  File "/srv/homeassistant/lib/python3.5/site-packages/googlemaps/client.py", line 276, in _get_body
    raise googlemaps.exceptions._RetriableRequest()
googlemaps.exceptions._RetriableRequest

During handling of the above exception, another exception occurred:

Traceback (most recent call last):
  File "/srv/homeassistant/lib/python3.5/site-packages/googlemaps/client.py", line 253, in _request
    result = self._get_body(response)
  File "/srv/homeassistant/lib/python3.5/site-packages/googlemaps/client.py", line 276, in _get_body
    raise googlemaps.exceptions._RetriableRequest()
googlemaps.exceptions._RetriableRequest

During handling of the above exception, another exception occurred:

Traceback (most recent call last):
  File "/srv/homeassistant/lib/python3.5/site-packages/googlemaps/client.py", line 253, in _request
    result = self._get_body(response)
  File "/srv/homeassistant/lib/python3.5/site-packages/googlemaps/client.py", line 276, in _get_body
    raise googlemaps.exceptions._RetriableRequest()
googlemaps.exceptions._RetriableRequest

During handling of the above exception, another exception occurred:

Traceback (most recent call last):
  File "/srv/homeassistant/lib/python3.5/site-packages/googlemaps/client.py", line 253, in _request
    result = self._get_body(response)
  File "/srv/homeassistant/lib/python3.5/site-packages/googlemaps/client.py", line 276, in _get_body
    raise googlemaps.exceptions._RetriableRequest()
googlemaps.exceptions._RetriableRequest

During handling of the above exception, another exception occurred:

Traceback (most recent call last):
  File "/srv/homeassistant/lib/python3.5/site-packages/googlemaps/client.py", line 253, in _request
    result = self._get_body(response)
  File "/srv/homeassistant/lib/python3.5/site-packages/googlemaps/client.py", line 276, in _get_body
    raise googlemaps.exceptions._RetriableRequest()
googlemaps.exceptions._RetriableRequest

During handling of the above exception, another exception occurred:

Traceback (most recent call last):
  File "/srv/homeassistant/lib/python3.5/site-packages/googlemaps/client.py", line 253, in _request
    result = self._get_body(response)
  File "/srv/homeassistant/lib/python3.5/site-packages/googlemaps/client.py", line 276, in _get_body
    raise googlemaps.exceptions._RetriableRequest()
googlemaps.exceptions._RetriableRequest

During handling of the above exception, another exception occurred:

Traceback (most recent call last):
  File "/srv/homeassistant/lib/python3.5/site-packages/googlemaps/client.py", line 253, in _request
    result = self._get_body(response)
  File "/srv/homeassistant/lib/python3.5/site-packages/googlemaps/client.py", line 276, in _get_body
    raise googlemaps.exceptions._RetriableRequest()
googlemaps.exceptions._RetriableRequest

During handling of the above exception, another exception occurred:

Traceback (most recent call last):
  File "/srv/homeassistant/lib/python3.5/site-packages/googlemaps/client.py", line 253, in _request
    result = self._get_body(response)
  File "/srv/homeassistant/lib/python3.5/site-packages/googlemaps/client.py", line 276, in _get_body
    raise googlemaps.exceptions._RetriableRequest()
googlemaps.exceptions._RetriableRequest

During handling of the above exception, another exception occurred:

Traceback (most recent call last):
  File "/srv/homeassistant/lib/python3.5/site-packages/googlemaps/client.py", line 253, in _request
    result = self._get_body(response)
  File "/srv/homeassistant/lib/python3.5/site-packages/googlemaps/client.py", line 276, in _get_body
    raise googlemaps.exceptions._RetriableRequest()
googlemaps.exceptions._RetriableRequest

During handling of the above exception, another exception occurred:

Traceback (most recent call last):
  File "/srv/homeassistant/lib/python3.5/site-packages/googlemaps/client.py", line 253, in _request
    result = self._get_body(response)
  File "/srv/homeassistant/lib/python3.5/site-packages/googlemaps/client.py", line 276, in _get_body
    raise googlemaps.exceptions._RetriableRequest()
googlemaps.exceptions._RetriableRequest

During handling of the above exception, another exception occurred:

Traceback (most recent call last):
  File "/srv/homeassistant/lib/python3.5/site-packages/googlemaps/client.py", line 253, in _request
    result = self._get_body(response)
  File "/srv/homeassistant/lib/python3.5/site-packages/googlemaps/client.py", line 276, in _get_body
    raise googlemaps.exceptions._RetriableRequest()
googlemaps.exceptions._RetriableRequest

During handling of the above exception, another exception occurred:

Traceback (most recent call last):
  File "/srv/homeassistant/lib/python3.5/site-packages/homeassistant/helpers/entity.py", line 220, in async_update_ha_state
    await self.async_device_update()
  File "/srv/homeassistant/lib/python3.5/site-packages/homeassistant/helpers/entity.py", line 377, in async_device_update
    await self.hass.async_add_executor_job(self.update)
  File "/usr/lib/python3.5/asyncio/futures.py", line 380, in __iter__
    yield self  # This tells Task to wait for completion.
  File "/usr/lib/python3.5/asyncio/tasks.py", line 304, in _wakeup
    future.result()
  File "/usr/lib/python3.5/asyncio/futures.py", line 293, in result
    raise self._exception
  File "/usr/lib/python3.5/concurrent/futures/thread.py", line 55, in run
    result = self.fn(*self.args, **self.kwargs)
  File "/srv/homeassistant/lib/python3.5/site-packages/homeassistant/util/__init__.py", line 224, in wrapper
    result = method(*args, **kwargs)
  File "/srv/homeassistant/lib/python3.5/site-packages/homeassistant/components/google_travel_time/sensor.py", line 225, in update
    self._origin, self._destination, **options_copy)
  File "/srv/homeassistant/lib/python3.5/site-packages/googlemaps/client.py", line 356, in wrapper
    result = func(*args, **kwargs)
  File "/srv/homeassistant/lib/python3.5/site-packages/googlemaps/distance_matrix.py", line 130, in distance_matrix
    return client._request("/maps/api/distancematrix/json", params)
  File "/srv/homeassistant/lib/python3.5/site-packages/googlemaps/client.py", line 260, in _request
    extract_body, requests_kwargs, post_json)
  File "/srv/homeassistant/lib/python3.5/site-packages/googlemaps/client.py", line 260, in _request
    extract_body, requests_kwargs, post_json)
  File "/srv/homeassistant/lib/python3.5/site-packages/googlemaps/client.py", line 260, in _request
    extract_body, requests_kwargs, post_json)
  File "/srv/homeassistant/lib/python3.5/site-packages/googlemaps/client.py", line 260, in _request
    extract_body, requests_kwargs, post_json)
  File "/srv/homeassistant/lib/python3.5/site-packages/googlemaps/client.py", line 260, in _request
    extract_body, requests_kwargs, post_json)
  File "/srv/homeassistant/lib/python3.5/site-packages/googlemaps/client.py", line 260, in _request
    extract_body, requests_kwargs, post_json)
  File "/srv/homeassistant/lib/python3.5/site-packages/googlemaps/client.py", line 260, in _request
    extract_body, requests_kwargs, post_json)
  File "/srv/homeassistant/lib/python3.5/site-packages/googlemaps/client.py", line 260, in _request
    extract_body, requests_kwargs, post_json)
  File "/srv/homeassistant/lib/python3.5/site-packages/googlemaps/client.py", line 260, in _request
    extract_body, requests_kwargs, post_json)
  File "/srv/homeassistant/lib/python3.5/site-packages/googlemaps/client.py", line 260, in _request
    extract_body, requests_kwargs, post_json)
  File "/srv/homeassistant/lib/python3.5/site-packages/googlemaps/client.py", line 260, in _request
    extract_body, requests_kwargs, post_json)
  File "/srv/homeassistant/lib/python3.5/site-packages/googlemaps/client.py", line 260, in _request
    extract_body, requests_kwargs, post_json)
  File "/srv/homeassistant/lib/python3.5/site-packages/googlemaps/client.py", line 203, in _request
    raise googlemaps.exceptions.Timeout()
googlemaps.exceptions.Timeout
2019-05-24 21:16:05 WARNING (MainThread) [homeassistant.helpers.entity] Update of sensor.to_hannover is taking over 10 seconds
2019-05-24 21:16:26 WARNING (MainThread) [homeassistant.components.sensor] Updating google_travel_time sensor took longer than the scheduled update interval 0:00:30
2019-05-24 21:16:57 WARNING (MainThread) [homeassistant.components.sensor] Updating google_travel_time sensor took longer than the scheduled update interval 0:00:30
2019-05-24 21:17:12 ERROR (MainThread) [homeassistant.helpers.entity] Update for sensor.to_hannover fails
Traceback (most recent call last):
  File "/srv/homeassistant/lib/python3.5/site-packages/googlemaps/client.py", line 253, in _request
    result = self._get_body(response)
  File "/srv/homeassistant/lib/python3.5/site-packages/googlemaps/client.py", line 276, in _get_body
    raise googlemaps.exceptions._RetriableRequest()
googlemaps.exceptions._RetriableRequest

During handling of the above exception, another exception occurred:

Traceback (most recent call last):
  File "/srv/homeassistant/lib/python3.5/site-packages/googlemaps/client.py", line 253, in _request
    result = self._get_body(response)
  File "/srv/homeassistant/lib/python3.5/site-packages/googlemaps/client.py", line 276, in _get_body
    raise googlemaps.exceptions._RetriableRequest()
googlemaps.exceptions._RetriableRequest

During handling of the above exception, another exception occurred:

Traceback (most recent call last):
  File "/srv/homeassistant/lib/python3.5/site-packages/googlemaps/client.py", line 253, in _request
    result = self._get_body(response)
  File "/srv/homeassistant/lib/python3.5/site-packages/googlemaps/client.py", line 276, in _get_body
    raise googlemaps.exceptions._RetriableRequest()
googlemaps.exceptions._RetriableRequest

During handling of the above exception, another exception occurred:

Traceback (most recent call last):
  File "/srv/homeassistant/lib/python3.5/site-packages/googlemaps/client.py", line 253, in _request
    result = self._get_body(response)
  File "/srv/homeassistant/lib/python3.5/site-packages/googlemaps/client.py", line 276, in _get_body
    raise googlemaps.exceptions._RetriableRequest()
googlemaps.exceptions._RetriableRequest

During handling of the above exception, another exception occurred:

Traceback (most recent call last):
  File "/srv/homeassistant/lib/python3.5/site-packages/googlemaps/client.py", line 253, in _request
    result = self._get_body(response)
  File "/srv/homeassistant/lib/python3.5/site-packages/googlemaps/client.py", line 276, in _get_body
    raise googlemaps.exceptions._RetriableRequest()
googlemaps.exceptions._RetriableRequest

During handling of the above exception, another exception occurred:

Traceback (most recent call last):
  File "/srv/homeassistant/lib/python3.5/site-packages/googlemaps/client.py", line 253, in _request
    result = self._get_body(response)
  File "/srv/homeassistant/lib/python3.5/site-packages/googlemaps/client.py", line 276, in _get_body
    raise googlemaps.exceptions._RetriableRequest()
googlemaps.exceptions._RetriableRequest

During handling of the above exception, another exception occurred:

Traceback (most recent call last):
  File "/srv/homeassistant/lib/python3.5/site-packages/googlemaps/client.py", line 253, in _request
    result = self._get_body(response)
  File "/srv/homeassistant/lib/python3.5/site-packages/googlemaps/client.py", line 276, in _get_body
    raise googlemaps.exceptions._RetriableRequest()
googlemaps.exceptions._RetriableRequest

During handling of the above exception, another exception occurred:

Traceback (most recent call last):
  File "/srv/homeassistant/lib/python3.5/site-packages/googlemaps/client.py", line 253, in _request
    result = self._get_body(response)
  File "/srv/homeassistant/lib/python3.5/site-packages/googlemaps/client.py", line 276, in _get_body
    raise googlemaps.exceptions._RetriableRequest()
googlemaps.exceptions._RetriableRequest

During handling of the above exception, another exception occurred:

Traceback (most recent call last):
  File "/srv/homeassistant/lib/python3.5/site-packages/googlemaps/client.py", line 253, in _request
    result = self._get_body(response)
  File "/srv/homeassistant/lib/python3.5/site-packages/googlemaps/client.py", line 276, in _get_body
    raise googlemaps.exceptions._RetriableRequest()
googlemaps.exceptions._RetriableRequest

During handling of the above exception, another exception occurred:

Traceback (most recent call last):
  File "/srv/homeassistant/lib/python3.5/site-packages/googlemaps/client.py", line 253, in _request
    result = self._get_body(response)
  File "/srv/homeassistant/lib/python3.5/site-packages/googlemaps/client.py", line 276, in _get_body
    raise googlemaps.exceptions._RetriableRequest()
googlemaps.exceptions._RetriableRequest

During handling of the above exception, another exception occurred:

Traceback (most recent call last):
  File "/srv/homeassistant/lib/python3.5/site-packages/googlemaps/client.py", line 253, in _request
    result = self._get_body(response)
  File "/srv/homeassistant/lib/python3.5/site-packages/googlemaps/client.py", line 276, in _get_body
    raise googlemaps.exceptions._RetriableRequest()
googlemaps.exceptions._RetriableRequest

During handling of the above exception, another exception occurred:

Traceback (most recent call last):
  File "/srv/homeassistant/lib/python3.5/site-packages/googlemaps/client.py", line 253, in _request
    result = self._get_body(response)
  File "/srv/homeassistant/lib/python3.5/site-packages/googlemaps/client.py", line 276, in _get_body
    raise googlemaps.exceptions._RetriableRequest()
googlemaps.exceptions._RetriableRequest

During handling of the above exception, another exception occurred:

Traceback (most recent call last):
  File "/srv/homeassistant/lib/python3.5/site-packages/homeassistant/helpers/entity.py", line 220, in async_update_ha_state
    await self.async_device_update()
  File "/srv/homeassistant/lib/python3.5/site-packages/homeassistant/helpers/entity.py", line 377, in async_device_update
    await self.hass.async_add_executor_job(self.update)
  File "/usr/lib/python3.5/asyncio/futures.py", line 380, in __iter__
    yield self  # This tells Task to wait for completion.
  File "/usr/lib/python3.5/asyncio/tasks.py", line 304, in _wakeup
    future.result()
  File "/usr/lib/python3.5/asyncio/futures.py", line 293, in result
    raise self._exception
  File "/usr/lib/python3.5/concurrent/futures/thread.py", line 55, in run
    result = self.fn(*self.args, **self.kwargs)
  File "/srv/homeassistant/lib/python3.5/site-packages/homeassistant/util/__init__.py", line 224, in wrapper
    result = method(*args, **kwargs)
  File "/srv/homeassistant/lib/python3.5/site-packages/homeassistant/components/google_travel_time/sensor.py", line 225, in update
    self._origin, self._destination, **options_copy)
  File "/srv/homeassistant/lib/python3.5/site-packages/googlemaps/client.py", line 356, in wrapper
    result = func(*args, **kwargs)
  File "/srv/homeassistant/lib/python3.5/site-packages/googlemaps/distance_matrix.py", line 130, in distance_matrix
    return client._request("/maps/api/distancematrix/json", params)
  File "/srv/homeassistant/lib/python3.5/site-packages/googlemaps/client.py", line 260, in _request
    extract_body, requests_kwargs, post_json)
  File "/srv/homeassistant/lib/python3.5/site-packages/googlemaps/client.py", line 260, in _request
    extract_body, requests_kwargs, post_json)
  File "/srv/homeassistant/lib/python3.5/site-packages/googlemaps/client.py", line 260, in _request
    extract_body, requests_kwargs, post_json)
  File "/srv/homeassistant/lib/python3.5/site-packages/googlemaps/client.py", line 260, in _request
    extract_body, requests_kwargs, post_json)
  File "/srv/homeassistant/lib/python3.5/site-packages/googlemaps/client.py", line 260, in _request
    extract_body, requests_kwargs, post_json)
  File "/srv/homeassistant/lib/python3.5/site-packages/googlemaps/client.py", line 260, in _request
    extract_body, requests_kwargs, post_json)
  File "/srv/homeassistant/lib/python3.5/site-packages/googlemaps/client.py", line 260, in _request
    extract_body, requests_kwargs, post_json)
  File "/srv/homeassistant/lib/python3.5/site-packages/googlemaps/client.py", line 260, in _request
    extract_body, requests_kwargs, post_json)
  File "/srv/homeassistant/lib/python3.5/site-packages/googlemaps/client.py", line 260, in _request
    extract_body, requests_kwargs, post_json)
  File "/srv/homeassistant/lib/python3.5/site-packages/googlemaps/client.py", line 260, in _request
    extract_body, requests_kwargs, post_json)
  File "/srv/homeassistant/lib/python3.5/site-packages/googlemaps/client.py", line 260, in _request
    extract_body, requests_kwargs, post_json)
  File "/srv/homeassistant/lib/python3.5/site-packages/googlemaps/client.py", line 260, in _request
    extract_body, requests_kwargs, post_json)
  File "/srv/homeassistant/lib/python3.5/site-packages/googlemaps/client.py", line 203, in _request
    raise googlemaps.exceptions.Timeout()
googlemaps.exceptions.Timeout
2019-05-24 21:17:38 WARNING (MainThread) [homeassistant.helpers.entity] Update of sensor.to_hannover is taking over 10 seconds
2019-05-24 21:17:59 WARNING (MainThread) [homeassistant.components.sensor] Updating google_travel_time sensor took longer than the scheduled update interval 0:00:30
2019-05-24 21:18:30 WARNING (MainThread) [homeassistant.components.sensor] Updating google_travel_time sensor took longer than the scheduled update interval 0:00:30
2019-05-24 21:18:30 ERROR (MainThread) [homeassistant.helpers.entity] Update for sensor.to_hannover fails
Traceback (most recent call last):
  File "/srv/homeassistant/lib/python3.5/site-packages/googlemaps/client.py", line 253, in _request
    result = self._get_body(response)
  File "/srv/homeassistant/lib/python3.5/site-packages/googlemaps/client.py", line 276, in _get_body
    raise googlemaps.exceptions._RetriableRequest()
googlemaps.exceptions._RetriableRequest

During handling of the above exception, another exception occurred:

Traceback (most recent call last):
  File "/srv/homeassistant/lib/python3.5/site-packages/googlemaps/client.py", line 253, in _request
    result = self._get_body(response)
  File "/srv/homeassistant/lib/python3.5/site-packages/googlemaps/client.py", line 276, in _get_body
    raise googlemaps.exceptions._RetriableRequest()
googlemaps.exceptions._RetriableRequest

During handling of the above exception, another exception occurred:

Traceback (most recent call last):
  File "/srv/homeassistant/lib/python3.5/site-packages/googlemaps/client.py", line 253, in _request
    result = self._get_body(response)
  File "/srv/homeassistant/lib/python3.5/site-packages/googlemaps/client.py", line 276, in _get_body
    raise googlemaps.exceptions._RetriableRequest()
googlemaps.exceptions._RetriableRequest

During handling of the above exception, another exception occurred:

Traceback (most recent call last):
  File "/srv/homeassistant/lib/python3.5/site-packages/googlemaps/client.py", line 253, in _request
    result = self._get_body(response)
  File "/srv/homeassistant/lib/python3.5/site-packages/googlemaps/client.py", line 276, in _get_body
    raise googlemaps.exceptions._RetriableRequest()
googlemaps.exceptions._RetriableRequest

During handling of the above exception, another exception occurred:

Traceback (most recent call last):
  File "/srv/homeassistant/lib/python3.5/site-packages/googlemaps/client.py", line 253, in _request
    result = self._get_body(response)
  File "/srv/homeassistant/lib/python3.5/site-packages/googlemaps/client.py", line 276, in _get_body
    raise googlemaps.exceptions._RetriableRequest()
googlemaps.exceptions._RetriableRequest

During handling of the above exception, another exception occurred:

Traceback (most recent call last):
  File "/srv/homeassistant/lib/python3.5/site-packages/googlemaps/client.py", line 253, in _request
    result = self._get_body(response)
  File "/srv/homeassistant/lib/python3.5/site-packages/googlemaps/client.py", line 276, in _get_body
    raise googlemaps.exceptions._RetriableRequest()
googlemaps.exceptions._RetriableRequest

During handling of the above exception, another exception occurred:

Traceback (most recent call last):
  File "/srv/homeassistant/lib/python3.5/site-packages/googlemaps/client.py", line 253, in _request
    result = self._get_body(response)
  File "/srv/homeassistant/lib/python3.5/site-packages/googlemaps/client.py", line 276, in _get_body
    raise googlemaps.exceptions._RetriableRequest()
googlemaps.exceptions._RetriableRequest

During handling of the above exception, another exception occurred:

Traceback (most recent call last):
  File "/srv/homeassistant/lib/python3.5/site-packages/googlemaps/client.py", line 253, in _request
    result = self._get_body(response)
  File "/srv/homeassistant/lib/python3.5/site-packages/googlemaps/client.py", line 276, in _get_body
    raise googlemaps.exceptions._RetriableRequest()
googlemaps.exceptions._RetriableRequest

During handling of the above exception, another exception occurred:

Traceback (most recent call last):
  File "/srv/homeassistant/lib/python3.5/site-packages/googlemaps/client.py", line 253, in _request
    result = self._get_body(response)
  File "/srv/homeassistant/lib/python3.5/site-packages/googlemaps/client.py", line 276, in _get_body
    raise googlemaps.exceptions._RetriableRequest()
googlemaps.exceptions._RetriableRequest

During handling of the above exception, another exception occurred:

Traceback (most recent call last):
  File "/srv/homeassistant/lib/python3.5/site-packages/googlemaps/client.py", line 253, in _request
    result = self._get_body(response)
  File "/srv/homeassistant/lib/python3.5/site-packages/googlemaps/client.py", line 276, in _get_body
    raise googlemaps.exceptions._RetriableRequest()
googlemaps.exceptions._RetriableRequest

During handling of the above exception, another exception occurred:

Traceback (most recent call last):
  File "/srv/homeassistant/lib/python3.5/site-packages/googlemaps/client.py", line 253, in _request
    result = self._get_body(response)
  File "/srv/homeassistant/lib/python3.5/site-packages/googlemaps/client.py", line 276, in _get_body
    raise googlemaps.exceptions._RetriableRequest()
googlemaps.exceptions._RetriableRequest

During handling of the above exception, another exception occurred:

Traceback (most recent call last):
  File "/srv/homeassistant/lib/python3.5/site-packages/homeassistant/helpers/entity.py", line 220, in async_update_ha_state
    await self.async_device_update()
  File "/srv/homeassistant/lib/python3.5/site-packages/homeassistant/helpers/entity.py", line 377, in async_device_update
    await self.hass.async_add_executor_job(self.update)
  File "/usr/lib/python3.5/asyncio/futures.py", line 380, in __iter__
    yield self  # This tells Task to wait for completion.
  File "/usr/lib/python3.5/asyncio/tasks.py", line 304, in _wakeup
    future.result()
  File "/usr/lib/python3.5/asyncio/futures.py", line 293, in result
    raise self._exception
  File "/usr/lib/python3.5/concurrent/futures/thread.py", line 55, in run
    result = self.fn(*self.args, **self.kwargs)
  File "/srv/homeassistant/lib/python3.5/site-packages/homeassistant/util/__init__.py", line 224, in wrapper
    result = method(*args, **kwargs)
  File "/srv/homeassistant/lib/python3.5/site-packages/homeassistant/components/google_travel_time/sensor.py", line 225, in update
    self._origin, self._destination, **options_copy)
  File "/srv/homeassistant/lib/python3.5/site-packages/googlemaps/client.py", line 356, in wrapper
    result = func(*args, **kwargs)
  File "/srv/homeassistant/lib/python3.5/site-packages/googlemaps/distance_matrix.py", line 130, in distance_matrix
    return client._request("/maps/api/distancematrix/json", params)
  File "/srv/homeassistant/lib/python3.5/site-packages/googlemaps/client.py", line 260, in _request
    extract_body, requests_kwargs, post_json)
  File "/srv/homeassistant/lib/python3.5/site-packages/googlemaps/client.py", line 260, in _request
    extract_body, requests_kwargs, post_json)
  File "/srv/homeassistant/lib/python3.5/site-packages/googlemaps/client.py", line 260, in _request
    extract_body, requests_kwargs, post_json)
  File "/srv/homeassistant/lib/python3.5/site-packages/googlemaps/client.py", line 260, in _request
    extract_body, requests_kwargs, post_json)
  File "/srv/homeassistant/lib/python3.5/site-packages/googlemaps/client.py", line 260, in _request
    extract_body, requests_kwargs, post_json)
  File "/srv/homeassistant/lib/python3.5/site-packages/googlemaps/client.py", line 260, in _request
    extract_body, requests_kwargs, post_json)
  File "/srv/homeassistant/lib/python3.5/site-packages/googlemaps/client.py", line 260, in _request
    extract_body, requests_kwargs, post_json)
  File "/srv/homeassistant/lib/python3.5/site-packages/googlemaps/client.py", line 260, in _request
    extract_body, requests_kwargs, post_json)
  File "/srv/homeassistant/lib/python3.5/site-packages/googlemaps/client.py", line 260, in _request
    extract_body, requests_kwargs, post_json)
  File "/srv/homeassistant/lib/python3.5/site-packages/googlemaps/client.py", line 260, in _request
    extract_body, requests_kwargs, post_json)
  File "/srv/homeassistant/lib/python3.5/site-packages/googlemaps/client.py", line 260, in _request
    extract_body, requests_kwargs, post_json)
  File "/srv/homeassistant/lib/python3.5/site-packages/googlemaps/client.py", line 203, in _request
    raise googlemaps.exceptions.Timeout()
googlemaps.exceptions.Timeout
2019-05-24 21:19:11 WARNING (MainThread) [homeassistant.helpers.entity] Update of sensor.to_hannover is taking over 10 seconds
2019-05-24 21:19:32 WARNING (MainThread) [homeassistant.components.sensor] Updating google_travel_time sensor took longer than the scheduled update interval 0:00:30
2019-05-24 21:20:01 ERROR (MainThread) [homeassistant.helpers.entity] Update for sensor.to_hannover fails
Traceback (most recent call last):
  File "/srv/homeassistant/lib/python3.5/site-packages/googlemaps/client.py", line 253, in _request
    result = self._get_body(response)
  File "/srv/homeassistant/lib/python3.5/site-packages/googlemaps/client.py", line 276, in _get_body
    raise googlemaps.exceptions._RetriableRequest()
googlemaps.exceptions._RetriableRequest

During handling of the above exception, another exception occurred:

Traceback (most recent call last):
  File "/srv/homeassistant/lib/python3.5/site-packages/googlemaps/client.py", line 253, in _request
    result = self._get_body(response)
  File "/srv/homeassistant/lib/python3.5/site-packages/googlemaps/client.py", line 276, in _get_body
    raise googlemaps.exceptions._RetriableRequest()
googlemaps.exceptions._RetriableRequest

During handling of the above exception, another exception occurred:

Traceback (most recent call last):
  File "/srv/homeassistant/lib/python3.5/site-packages/googlemaps/client.py", line 253, in _request
    result = self._get_body(response)
  File "/srv/homeassistant/lib/python3.5/site-packages/googlemaps/client.py", line 276, in _get_body
    raise googlemaps.exceptions._RetriableRequest()
googlemaps.exceptions._RetriableRequest

During handling of the above exception, another exception occurred:

Traceback (most recent call last):
  File "/srv/homeassistant/lib/python3.5/site-packages/googlemaps/client.py", line 253, in _request
    result = self._get_body(response)
  File "/srv/homeassistant/lib/python3.5/site-packages/googlemaps/client.py", line 276, in _get_body
    raise googlemaps.exceptions._RetriableRequest()
googlemaps.exceptions._RetriableRequest

During handling of the above exception, another exception occurred:

Traceback (most recent call last):
  File "/srv/homeassistant/lib/python3.5/site-packages/googlemaps/client.py", line 253, in _request
    result = self._get_body(response)
  File "/srv/homeassistant/lib/python3.5/site-packages/googlemaps/client.py", line 276, in _get_body
    raise googlemaps.exceptions._RetriableRequest()
googlemaps.exceptions._RetriableRequest

During handling of the above exception, another exception occurred:

Traceback (most recent call last):
  File "/srv/homeassistant/lib/python3.5/site-packages/googlemaps/client.py", line 253, in _request
    result = self._get_body(response)
  File "/srv/homeassistant/lib/python3.5/site-packages/googlemaps/client.py", line 276, in _get_body
    raise googlemaps.exceptions._RetriableRequest()
googlemaps.exceptions._RetriableRequest

During handling of the above exception, another exception occurred:

Traceback (most recent call last):
  File "/srv/homeassistant/lib/python3.5/site-packages/googlemaps/client.py", line 253, in _request
    result = self._get_body(response)
  File "/srv/homeassistant/lib/python3.5/site-packages/googlemaps/client.py", line 276, in _get_body
    raise googlemaps.exceptions._RetriableRequest()
googlemaps.exceptions._RetriableRequest

During handling of the above exception, another exception occurred:

Traceback (most recent call last):
  File "/srv/homeassistant/lib/python3.5/site-packages/googlemaps/client.py", line 253, in _request
    result = self._get_body(response)
  File "/srv/homeassistant/lib/python3.5/site-packages/googlemaps/client.py", line 276, in _get_body
    raise googlemaps.exceptions._RetriableRequest()
googlemaps.exceptions._RetriableRequest

During handling of the above exception, another exception occurred:

Traceback (most recent call last):
  File "/srv/homeassistant/lib/python3.5/site-packages/googlemaps/client.py", line 253, in _request
    result = self._get_body(response)
  File "/srv/homeassistant/lib/python3.5/site-packages/googlemaps/client.py", line 276, in _get_body
    raise googlemaps.exceptions._RetriableRequest()
googlemaps.exceptions._RetriableRequest

During handling of the above exception, another exception occurred:

Traceback (most recent call last):
  File "/srv/homeassistant/lib/python3.5/site-packages/googlemaps/client.py", line 253, in _request
    result = self._get_body(response)
  File "/srv/homeassistant/lib/python3.5/site-packages/googlemaps/client.py", line 276, in _get_body
    raise googlemaps.exceptions._RetriableRequest()
googlemaps.exceptions._RetriableRequest

During handling of the above exception, another exception occurred:

Traceback (most recent call last):
  File "/srv/homeassistant/lib/python3.5/site-packages/googlemaps/client.py", line 253, in _request
    result = self._get_body(response)
  File "/srv/homeassistant/lib/python3.5/site-packages/googlemaps/client.py", line 276, in _get_body
    raise googlemaps.exceptions._RetriableRequest()
googlemaps.exceptions._RetriableRequest

During handling of the above exception, another exception occurred:

Traceback (most recent call last):
  File "/srv/homeassistant/lib/python3.5/site-packages/homeassistant/helpers/entity.py", line 220, in async_update_ha_state
    await self.async_device_update()
  File "/srv/homeassistant/lib/python3.5/site-packages/homeassistant/helpers/entity.py", line 377, in async_device_update
    await self.hass.async_add_executor_job(self.update)
  File "/usr/lib/python3.5/asyncio/futures.py", line 380, in __iter__
    yield self  # This tells Task to wait for completion.
  File "/usr/lib/python3.5/asyncio/tasks.py", line 304, in _wakeup
    future.result()
  File "/usr/lib/python3.5/asyncio/futures.py", line 293, in result
    raise self._exception
  File "/usr/lib/python3.5/concurrent/futures/thread.py", line 55, in run
    result = self.fn(*self.args, **self.kwargs)
  File "/srv/homeassistant/lib/python3.5/site-packages/homeassistant/util/__init__.py", line 224, in wrapper
    result = method(*args, **kwargs)
  File "/srv/homeassistant/lib/python3.5/site-packages/homeassistant/components/google_travel_time/sensor.py", line 225, in update
    self._origin, self._destination, **options_copy)
  File "/srv/homeassistant/lib/python3.5/site-packages/googlemaps/client.py", line 356, in wrapper
    result = func(*args, **kwargs)
  File "/srv/homeassistant/lib/python3.5/site-packages/googlemaps/distance_matrix.py", line 130, in distance_matrix
    return client._request("/maps/api/distancematrix/json", params)
  File "/srv/homeassistant/lib/python3.5/site-packages/googlemaps/client.py", line 260, in _request
    extract_body, requests_kwargs, post_json)
  File "/srv/homeassistant/lib/python3.5/site-packages/googlemaps/client.py", line 260, in _request
    extract_body, requests_kwargs, post_json)
  File "/srv/homeassistant/lib/python3.5/site-packages/googlemaps/client.py", line 260, in _request
    extract_body, requests_kwargs, post_json)
  File "/srv/homeassistant/lib/python3.5/site-packages/googlemaps/client.py", line 260, in _request
    extract_body, requests_kwargs, post_json)
  File "/srv/homeassistant/lib/python3.5/site-packages/googlemaps/client.py", line 260, in _request
    extract_body, requests_kwargs, post_json)
  File "/srv/homeassistant/lib/python3.5/site-packages/googlemaps/client.py", line 260, in _request
    extract_body, requests_kwargs, post_json)
  File "/srv/homeassistant/lib/python3.5/site-packages/googlemaps/client.py", line 260, in _request
    extract_body, requests_kwargs, post_json)
  File "/srv/homeassistant/lib/python3.5/site-packages/googlemaps/client.py", line 260, in _request
    extract_body, requests_kwargs, post_json)
  File "/srv/homeassistant/lib/python3.5/site-packages/googlemaps/client.py", line 260, in _request
    extract_body, requests_kwargs, post_json)
  File "/srv/homeassistant/lib/python3.5/site-packages/googlemaps/client.py", line 260, in _request
    extract_body, requests_kwargs, post_json)
  File "/srv/homeassistant/lib/python3.5/site-packages/googlemaps/client.py", line 260, in _request
    extract_body, requests_kwargs, post_json)
  File "/srv/homeassistant/lib/python3.5/site-packages/googlemaps/client.py", line 203, in _request
    raise googlemaps.exceptions.Timeout()
googlemaps.exceptions.Timeout
2019-05-24 21:20:13 WARNING (MainThread) [homeassistant.helpers.entity] Update of sensor.to_hannover is taking over 10 seconds
2019-05-24 21:20:34 WARNING (MainThread) [homeassistant.components.sensor] Updating google_travel_time sensor took longer than the scheduled update interval 0:00:30
2019-05-24 21:21:05 WARNING (MainThread) [homeassistant.components.sensor] Updating google_travel_time sensor took longer than the scheduled update interval 0:00:30
2019-05-24 21:21:32 ERROR (MainThread) [homeassistant.helpers.entity] Update for sensor.to_hannover fails
Traceback (most recent call last):
  File "/srv/homeassistant/lib/python3.5/site-packages/googlemaps/client.py", line 253, in _request
    result = self._get_body(response)
  File "/srv/homeassistant/lib/python3.5/site-packages/googlemaps/client.py", line 276, in _get_body
    raise googlemaps.exceptions._RetriableRequest()
googlemaps.exceptions._RetriableRequest

During handling of the above exception, another exception occurred:

Traceback (most recent call last):
  File "/srv/homeassistant/lib/python3.5/site-packages/googlemaps/client.py", line 253, in _request
    result = self._get_body(response)
  File "/srv/homeassistant/lib/python3.5/site-packages/googlemaps/client.py", line 276, in _get_body
    raise googlemaps.exceptions._RetriableRequest()
googlemaps.exceptions._RetriableRequest

During handling of the above exception, another exception occurred:

Traceback (most recent call last):
  File "/srv/homeassistant/lib/python3.5/site-packages/googlemaps/client.py", line 253, in _request
    result = self._get_body(response)
  File "/srv/homeassistant/lib/python3.5/site-packages/googlemaps/client.py", line 276, in _get_body
    raise googlemaps.exceptions._RetriableRequest()
googlemaps.exceptions._RetriableRequest

During handling of the above exception, another exception occurred:

Traceback (most recent call last):
  File "/srv/homeassistant/lib/python3.5/site-packages/googlemaps/client.py", line 253, in _request
    result = self._get_body(response)
  File "/srv/homeassistant/lib/python3.5/site-packages/googlemaps/client.py", line 276, in _get_body
    raise googlemaps.exceptions._RetriableRequest()
googlemaps.exceptions._RetriableRequest

During handling of the above exception, another exception occurred:

Traceback (most recent call last):
  File "/srv/homeassistant/lib/python3.5/site-packages/googlemaps/client.py", line 253, in _request
    result = self._get_body(response)
  File "/srv/homeassistant/lib/python3.5/site-packages/googlemaps/client.py", line 276, in _get_body
    raise googlemaps.exceptions._RetriableRequest()
googlemaps.exceptions._RetriableRequest

During handling of the above exception, another exception occurred:

Traceback (most recent call last):
  File "/srv/homeassistant/lib/python3.5/site-packages/googlemaps/client.py", line 253, in _request
    result = self._get_body(response)
  File "/srv/homeassistant/lib/python3.5/site-packages/googlemaps/client.py", line 276, in _get_body
    raise googlemaps.exceptions._RetriableRequest()
googlemaps.exceptions._RetriableRequest

During handling of the above exception, another exception occurred:

Traceback (most recent call last):
  File "/srv/homeassistant/lib/python3.5/site-packages/googlemaps/client.py", line 253, in _request
    result = self._get_body(response)
  File "/srv/homeassistant/lib/python3.5/site-packages/googlemaps/client.py", line 276, in _get_body
    raise googlemaps.exceptions._RetriableRequest()
googlemaps.exceptions._RetriableRequest

During handling of the above exception, another exception occurred:

Traceback (most recent call last):
  File "/srv/homeassistant/lib/python3.5/site-packages/googlemaps/client.py", line 253, in _request
    result = self._get_body(response)
  File "/srv/homeassistant/lib/python3.5/site-packages/googlemaps/client.py", line 276, in _get_body
    raise googlemaps.exceptions._RetriableRequest()
googlemaps.exceptions._RetriableRequest

During handling of the above exception, another exception occurred:

Traceback (most recent call last):
  File "/srv/homeassistant/lib/python3.5/site-packages/googlemaps/client.py", line 253, in _request
    result = self._get_body(response)
  File "/srv/homeassistant/lib/python3.5/site-packages/googlemaps/client.py", line 276, in _get_body
    raise googlemaps.exceptions._RetriableRequest()
googlemaps.exceptions._RetriableRequest

During handling of the above exception, another exception occurred:

Traceback (most recent call last):
  File "/srv/homeassistant/lib/python3.5/site-packages/googlemaps/client.py", line 253, in _request
    result = self._get_body(response)
  File "/srv/homeassistant/lib/python3.5/site-packages/googlemaps/client.py", line 276, in _get_body
    raise googlemaps.exceptions._RetriableRequest()
googlemaps.exceptions._RetriableRequest

During handling of the above exception, another exception occurred:

Traceback (most recent call last):
  File "/srv/homeassistant/lib/python3.5/site-packages/googlemaps/client.py", line 253, in _request
    result = self._get_body(response)
  File "/srv/homeassistant/lib/python3.5/site-packages/googlemaps/client.py", line 276, in _get_body
    raise googlemaps.exceptions._RetriableRequest()
googlemaps.exceptions._RetriableRequest

During handling of the above exception, another exception occurred:

Traceback (most recent call last):
  File "/srv/homeassistant/lib/python3.5/site-packages/googlemaps/client.py", line 253, in _request
    result = self._get_body(response)
  File "/srv/homeassistant/lib/python3.5/site-packages/googlemaps/client.py", line 276, in _get_body
    raise googlemaps.exceptions._RetriableRequest()
googlemaps.exceptions._RetriableRequest

During handling of the above exception, another exception occurred:

Traceback (most recent call last):
  File "/srv/homeassistant/lib/python3.5/site-packages/homeassistant/helpers/entity.py", line 220, in async_update_ha_state
    await self.async_device_update()
  File "/srv/homeassistant/lib/python3.5/site-packages/homeassistant/helpers/entity.py", line 377, in async_device_update
    await self.hass.async_add_executor_job(self.update)
  File "/usr/lib/python3.5/asyncio/futures.py", line 380, in __iter__
    yield self  # This tells Task to wait for completion.
  File "/usr/lib/python3.5/asyncio/tasks.py", line 304, in _wakeup
    future.result()
  File "/usr/lib/python3.5/asyncio/futures.py", line 293, in result
    raise self._exception
  File "/usr/lib/python3.5/concurrent/futures/thread.py", line 55, in run
    result = self.fn(*self.args, **self.kwargs)
  File "/srv/homeassistant/lib/python3.5/site-packages/homeassistant/util/__init__.py", line 224, in wrapper
    result = method(*args, **kwargs)
  File "/srv/homeassistant/lib/python3.5/site-packages/homeassistant/components/google_travel_time/sensor.py", line 225, in update
    self._origin, self._destination, **options_copy)
  File "/srv/homeassistant/lib/python3.5/site-packages/googlemaps/client.py", line 356, in wrapper
    result = func(*args, **kwargs)
  File "/srv/homeassistant/lib/python3.5/site-packages/googlemaps/distance_matrix.py", line 130, in distance_matrix
    return client._request("/maps/api/distancematrix/json", params)
  File "/srv/homeassistant/lib/python3.5/site-packages/googlemaps/client.py", line 260, in _request
    extract_body, requests_kwargs, post_json)
  File "/srv/homeassistant/lib/python3.5/site-packages/googlemaps/client.py", line 260, in _request
    extract_body, requests_kwargs, post_json)
  File "/srv/homeassistant/lib/python3.5/site-packages/googlemaps/client.py", line 260, in _request
    extract_body, requests_kwargs, post_json)
  File "/srv/homeassistant/lib/python3.5/site-packages/googlemaps/client.py", line 260, in _request
    extract_body, requests_kwargs, post_json)
  File "/srv/homeassistant/lib/python3.5/site-packages/googlemaps/client.py", line 260, in _request
    extract_body, requests_kwargs, post_json)
  File "/srv/homeassistant/lib/python3.5/site-packages/googlemaps/client.py", line 260, in _request
    extract_body, requests_kwargs, post_json)
  File "/srv/homeassistant/lib/python3.5/site-packages/googlemaps/client.py", line 260, in _request
    extract_body, requests_kwargs, post_json)
  File "/srv/homeassistant/lib/python3.5/site-packages/googlemaps/client.py", line 260, in _request
    extract_body, requests_kwargs, post_json)
  File "/srv/homeassistant/lib/python3.5/site-packages/googlemaps/client.py", line 260, in _request
    extract_body, requests_kwargs, post_json)
  File "/srv/homeassistant/lib/python3.5/site-packages/googlemaps/client.py", line 260, in _request
    extract_body, requests_kwargs, post_json)
  File "/srv/homeassistant/lib/python3.5/site-packages/googlemaps/client.py", line 260, in _request
    extract_body, requests_kwargs, post_json)
  File "/srv/homeassistant/lib/python3.5/site-packages/googlemaps/client.py", line 260, in _request
    extract_body, requests_kwargs, post_json)
  File "/srv/homeassistant/lib/python3.5/site-packages/googlemaps/client.py", line 203, in _request
    raise googlemaps.exceptions.Timeout()
googlemaps.exceptions.Timeout
2019-05-24 21:21:46 WARNING (MainThread) [homeassistant.helpers.entity] Update of sensor.to_hannover is taking over 10 seconds
2019-05-24 21:22:07 WARNING (MainThread) [homeassistant.components.sensor] Updating google_travel_time sensor took longer than the scheduled update interval 0:00:30
2019-05-24 21:22:38 WARNING (MainThread) [homeassistant.components.sensor] Updating google_travel_time sensor took longer than the scheduled update interval 0:00:30
2019-05-24 21:22:54 ERROR (MainThread) [homeassistant.helpers.entity] Update for sensor.to_hannover fails
Traceback (most recent call last):
  File "/srv/homeassistant/lib/python3.5/site-packages/googlemaps/client.py", line 253, in _request
    result = self._get_body(response)
  File "/srv/homeassistant/lib/python3.5/site-packages/googlemaps/client.py", line 276, in _get_body
    raise googlemaps.exceptions._RetriableRequest()
googlemaps.exceptions._RetriableRequest

During handling of the above exception, another exception occurred:

Traceback (most recent call last):
  File "/srv/homeassistant/lib/python3.5/site-packages/googlemaps/client.py", line 253, in _request
    result = self._get_body(response)
  File "/srv/homeassistant/lib/python3.5/site-packages/googlemaps/client.py", line 276, in _get_body
    raise googlemaps.exceptions._RetriableRequest()
googlemaps.exceptions._RetriableRequest

During handling of the above exception, another exception occurred:

Traceback (most recent call last):
  File "/srv/homeassistant/lib/python3.5/site-packages/googlemaps/client.py", line 253, in _request
    result = self._get_body(response)
  File "/srv/homeassistant/lib/python3.5/site-packages/googlemaps/client.py", line 276, in _get_body
    raise googlemaps.exceptions._RetriableRequest()
googlemaps.exceptions._RetriableRequest

During handling of the above exception, another exception occurred:

Traceback (most recent call last):
  File "/srv/homeassistant/lib/python3.5/site-packages/googlemaps/client.py", line 253, in _request
    result = self._get_body(response)
  File "/srv/homeassistant/lib/python3.5/site-packages/googlemaps/client.py", line 276, in _get_body
    raise googlemaps.exceptions._RetriableRequest()
googlemaps.exceptions._RetriableRequest

During handling of the above exception, another exception occurred:

Traceback (most recent call last):
  File "/srv/homeassistant/lib/python3.5/site-packages/googlemaps/client.py", line 253, in _request
    result = self._get_body(response)
  File "/srv/homeassistant/lib/python3.5/site-packages/googlemaps/client.py", line 276, in _get_body
    raise googlemaps.exceptions._RetriableRequest()
googlemaps.exceptions._RetriableRequest

During handling of the above exception, another exception occurred:

Traceback (most recent call last):
  File "/srv/homeassistant/lib/python3.5/site-packages/googlemaps/client.py", line 253, in _request
    result = self._get_body(response)
  File "/srv/homeassistant/lib/python3.5/site-packages/googlemaps/client.py", line 276, in _get_body
    raise googlemaps.exceptions._RetriableRequest()
googlemaps.exceptions._RetriableRequest

During handling of the above exception, another exception occurred:

Traceback (most recent call last):
  File "/srv/homeassistant/lib/python3.5/site-packages/googlemaps/client.py", line 253, in _request
    result = self._get_body(response)
  File "/srv/homeassistant/lib/python3.5/site-packages/googlemaps/client.py", line 276, in _get_body
    raise googlemaps.exceptions._RetriableRequest()
googlemaps.exceptions._RetriableRequest

During handling of the above exception, another exception occurred:

Traceback (most recent call last):
  File "/srv/homeassistant/lib/python3.5/site-packages/googlemaps/client.py", line 253, in _request
    result = self._get_body(response)
  File "/srv/homeassistant/lib/python3.5/site-packages/googlemaps/client.py", line 276, in _get_body
    raise googlemaps.exceptions._RetriableRequest()
googlemaps.exceptions._RetriableRequest

During handling of the above exception, another exception occurred:

Traceback (most recent call last):
  File "/srv/homeassistant/lib/python3.5/site-packages/googlemaps/client.py", line 253, in _request
    result = self._get_body(response)
  File "/srv/homeassistant/lib/python3.5/site-packages/googlemaps/client.py", line 276, in _get_body
    raise googlemaps.exceptions._RetriableRequest()
googlemaps.exceptions._RetriableRequest

During handling of the above exception, another exception occurred:

Traceback (most recent call last):
  File "/srv/homeassistant/lib/python3.5/site-packages/googlemaps/client.py", line 253, in _request
    result = self._get_body(response)
  File "/srv/homeassistant/lib/python3.5/site-packages/googlemaps/client.py", line 276, in _get_body
    raise googlemaps.exceptions._RetriableRequest()
googlemaps.exceptions._RetriableRequest

During handling of the above exception, another exception occurred:

Traceback (most recent call last):
  File "/srv/homeassistant/lib/python3.5/site-packages/googlemaps/client.py", line 253, in _request
    result = self._get_body(response)
  File "/srv/homeassistant/lib/python3.5/site-packages/googlemaps/client.py", line 276, in _get_body
    raise googlemaps.exceptions._RetriableRequest()
googlemaps.exceptions._RetriableRequest

During handling of the above exception, another exception occurred:

Traceback (most recent call last):
  File "/srv/homeassistant/lib/python3.5/site-packages/googlemaps/client.py", line 253, in _request
    result = self._get_body(response)
  File "/srv/homeassistant/lib/python3.5/site-packages/googlemaps/client.py", line 276, in _get_body
    raise googlemaps.exceptions._RetriableRequest()
googlemaps.exceptions._RetriableRequest

During handling of the above exception, another exception occurred:

Traceback (most recent call last):
  File "/srv/homeassistant/lib/python3.5/site-packages/homeassistant/helpers/entity.py", line 220, in async_update_ha_state
    await self.async_device_update()
  File "/srv/homeassistant/lib/python3.5/site-packages/homeassistant/helpers/entity.py", line 377, in async_device_update
    await self.hass.async_add_executor_job(self.update)
  File "/usr/lib/python3.5/asyncio/futures.py", line 380, in __iter__
    yield self  # This tells Task to wait for completion.
  File "/usr/lib/python3.5/asyncio/tasks.py", line 304, in _wakeup
    future.result()
  File "/usr/lib/python3.5/asyncio/futures.py", line 293, in result
    raise self._exception
  File "/usr/lib/python3.5/concurrent/futures/thread.py", line 55, in run
    result = self.fn(*self.args, **self.kwargs)
  File "/srv/homeassistant/lib/python3.5/site-packages/homeassistant/util/__init__.py", line 224, in wrapper
    result = method(*args, **kwargs)
  File "/srv/homeassistant/lib/python3.5/site-packages/homeassistant/components/google_travel_time/sensor.py", line 225, in update
    self._origin, self._destination, **options_copy)
  File "/srv/homeassistant/lib/python3.5/site-packages/googlemaps/client.py", line 356, in wrapper
    result = func(*args, **kwargs)
  File "/srv/homeassistant/lib/python3.5/site-packages/googlemaps/distance_matrix.py", line 130, in distance_matrix
    return client._request("/maps/api/distancematrix/json", params)
  File "/srv/homeassistant/lib/python3.5/site-packages/googlemaps/client.py", line 260, in _request
    extract_body, requests_kwargs, post_json)
  File "/srv/homeassistant/lib/python3.5/site-packages/googlemaps/client.py", line 260, in _request
    extract_body, requests_kwargs, post_json)
  File "/srv/homeassistant/lib/python3.5/site-packages/googlemaps/client.py", line 260, in _request
    extract_body, requests_kwargs, post_json)
  File "/srv/homeassistant/lib/python3.5/site-packages/googlemaps/client.py", line 260, in _request
    extract_body, requests_kwargs, post_json)
  File "/srv/homeassistant/lib/python3.5/site-packages/googlemaps/client.py", line 260, in _request
    extract_body, requests_kwargs, post_json)
  File "/srv/homeassistant/lib/python3.5/site-packages/googlemaps/client.py", line 260, in _request
    extract_body, requests_kwargs, post_json)
  File "/srv/homeassistant/lib/python3.5/site-packages/googlemaps/client.py", line 260, in _request
    extract_body, requests_kwargs, post_json)
  File "/srv/homeassistant/lib/python3.5/site-packages/googlemaps/client.py", line 260, in _request
    extract_body, requests_kwargs, post_json)
  File "/srv/homeassistant/lib/python3.5/site-packages/googlemaps/client.py", line 260, in _request
    extract_body, requests_kwargs, post_json)
  File "/srv/homeassistant/lib/python3.5/site-packages/googlemaps/client.py", line 260, in _request
    extract_body, requests_kwargs, post_json)
  File "/srv/homeassistant/lib/python3.5/site-packages/googlemaps/client.py", line 260, in _request
    extract_body, requests_kwargs, post_json)
  File "/srv/homeassistant/lib/python3.5/site-packages/googlemaps/client.py", line 260, in _request
    extract_body, requests_kwargs, post_json)
  File "/srv/homeassistant/lib/python3.5/site-packages/googlemaps/client.py", line 203, in _request
    raise googlemaps.exceptions.Timeout()
googlemaps.exceptions.Timeout
2019-05-24 21:23:19 WARNING (MainThread) [homeassistant.helpers.entity] Update of sensor.to_hannover is taking over 10 seconds
